2024-06-11 13:48:35 ERROR Traceback (most recent call last):
  File "/anaconda/envs/final_project_env/lib/python3.8/site-packages/wandb/apis/normalize.py", line 41, in wrapper
    return func(*args, **kwargs)
  File "/anaconda/envs/final_project_env/lib/python3.8/site-packages/wandb/sdk/internal/internal_api.py", line 1036, in sweep
    raise ValueError(f"Sweep {entity}/{project}/{sweep} not found")
ValueError: Sweep ravid-d/NLP2024_PROJECT_RavidDimant/7vmhyl5a not found

During handling of the above exception, another exception occurred:

Traceback (most recent call last):
  File "/anaconda/envs/final_project_env/lib/python3.8/site-packages/wandb/cli/cli.py", line 108, in wrapper
    return func(*args, **kwargs)
  File "/anaconda/envs/final_project_env/lib/python3.8/site-packages/wandb/cli/cli.py", line 1806, in agent
    wandb_agent.agent(sweep_id, entity=entity, project=project, count=count)
  File "/anaconda/envs/final_project_env/lib/python3.8/site-packages/wandb/wandb_agent.py", line 570, in agent
    return run_agent(
  File "/anaconda/envs/final_project_env/lib/python3.8/site-packages/wandb/wandb_agent.py", line 528, in run_agent
    agent.run()
  File "/anaconda/envs/final_project_env/lib/python3.8/site-packages/wandb/wandb_agent.py", line 190, in run
    sweep_obj = self._api.sweep(self._sweep_id, "{}")
  File "/anaconda/envs/final_project_env/lib/python3.8/site-packages/wandb/apis/internal.py", line 126, in sweep
    return self.api.sweep(*args, **kwargs)
  File "/anaconda/envs/final_project_env/lib/python3.8/site-packages/wandb/apis/normalize.py", line 87, in wrapper
    raise CommError(message, err).with_traceback(sys.exc_info()[2])
  File "/anaconda/envs/final_project_env/lib/python3.8/site-packages/wandb/apis/normalize.py", line 41, in wrapper
    return func(*args, **kwargs)
  File "/anaconda/envs/final_project_env/lib/python3.8/site-packages/wandb/sdk/internal/internal_api.py", line 1036, in sweep
    raise ValueError(f"Sweep {entity}/{project}/{sweep} not found")
wandb.errors.CommError: Sweep ravid-d/NLP2024_PROJECT_RavidDimant/7vmhyl5a not found

2024-06-11 13:48:35 ERROR Traceback (most recent call last):
  File "/anaconda/envs/final_project_env/lib/python3.8/site-packages/wandb/apis/normalize.py", line 41, in wrapper
    return func(*args, **kwargs)
  File "/anaconda/envs/final_project_env/lib/python3.8/site-packages/wandb/sdk/internal/internal_api.py", line 1036, in sweep
    raise ValueError(f"Sweep {entity}/{project}/{sweep} not found")
ValueError: Sweep ravid-d/NLP2024_PROJECT_RavidDimant/7vmhyl5a not found

During handling of the above exception, another exception occurred:

Traceback (most recent call last):
  File "/anaconda/envs/final_project_env/lib/python3.8/site-packages/wandb/cli/cli.py", line 108, in wrapper
    return func(*args, **kwargs)
  File "/anaconda/envs/final_project_env/lib/python3.8/site-packages/wandb/cli/cli.py", line 1806, in agent
    wandb_agent.agent(sweep_id, entity=entity, project=project, count=count)
  File "/anaconda/envs/final_project_env/lib/python3.8/site-packages/wandb/wandb_agent.py", line 570, in agent
    return run_agent(
  File "/anaconda/envs/final_project_env/lib/python3.8/site-packages/wandb/wandb_agent.py", line 528, in run_agent
    agent.run()
  File "/anaconda/envs/final_project_env/lib/python3.8/site-packages/wandb/wandb_agent.py", line 190, in run
    sweep_obj = self._api.sweep(self._sweep_id, "{}")
  File "/anaconda/envs/final_project_env/lib/python3.8/site-packages/wandb/apis/internal.py", line 126, in sweep
    return self.api.sweep(*args, **kwargs)
  File "/anaconda/envs/final_project_env/lib/python3.8/site-packages/wandb/apis/normalize.py", line 87, in wrapper
    raise CommError(message, err).with_traceback(sys.exc_info()[2])
  File "/anaconda/envs/final_project_env/lib/python3.8/site-packages/wandb/apis/normalize.py", line 41, in wrapper
    return func(*args, **kwargs)
  File "/anaconda/envs/final_project_env/lib/python3.8/site-packages/wandb/sdk/internal/internal_api.py", line 1036, in sweep
    raise ValueError(f"Sweep {entity}/{project}/{sweep} not found")
wandb.errors.CommError: Sweep ravid-d/NLP2024_PROJECT_RavidDimant/7vmhyl5a not found

2024-06-11 13:48:35 ERROR Traceback (most recent call last):
  File "/anaconda/envs/final_project_env/lib/python3.8/site-packages/wandb/apis/normalize.py", line 41, in wrapper
    return func(*args, **kwargs)
  File "/anaconda/envs/final_project_env/lib/python3.8/site-packages/wandb/sdk/internal/internal_api.py", line 1036, in sweep
    raise ValueError(f"Sweep {entity}/{project}/{sweep} not found")
ValueError: Sweep ravid-d/NLP2024_PROJECT_RavidDimant/7vmhyl5a not found

During handling of the above exception, another exception occurred:

Traceback (most recent call last):
  File "/anaconda/envs/final_project_env/lib/python3.8/site-packages/wandb/cli/cli.py", line 108, in wrapper
    return func(*args, **kwargs)
  File "/anaconda/envs/final_project_env/lib/python3.8/site-packages/wandb/cli/cli.py", line 1806, in agent
    wandb_agent.agent(sweep_id, entity=entity, project=project, count=count)
  File "/anaconda/envs/final_project_env/lib/python3.8/site-packages/wandb/wandb_agent.py", line 570, in agent
    return run_agent(
  File "/anaconda/envs/final_project_env/lib/python3.8/site-packages/wandb/wandb_agent.py", line 528, in run_agent
    agent.run()
  File "/anaconda/envs/final_project_env/lib/python3.8/site-packages/wandb/wandb_agent.py", line 190, in run
    sweep_obj = self._api.sweep(self._sweep_id, "{}")
  File "/anaconda/envs/final_project_env/lib/python3.8/site-packages/wandb/apis/internal.py", line 126, in sweep
    return self.api.sweep(*args, **kwargs)
  File "/anaconda/envs/final_project_env/lib/python3.8/site-packages/wandb/apis/normalize.py", line 87, in wrapper
    raise CommError(message, err).with_traceback(sys.exc_info()[2])
  File "/anaconda/envs/final_project_env/lib/python3.8/site-packages/wandb/apis/normalize.py", line 41, in wrapper
    return func(*args, **kwargs)
  File "/anaconda/envs/final_project_env/lib/python3.8/site-packages/wandb/sdk/internal/internal_api.py", line 1036, in sweep
    raise ValueError(f"Sweep {entity}/{project}/{sweep} not found")
wandb.errors.CommError: Sweep ravid-d/NLP2024_PROJECT_RavidDimant/7vmhyl5a not found

2024-06-11 13:48:35 ERROR Traceback (most recent call last):
  File "/anaconda/envs/final_project_env/lib/python3.8/site-packages/wandb/apis/normalize.py", line 41, in wrapper
    return func(*args, **kwargs)
  File "/anaconda/envs/final_project_env/lib/python3.8/site-packages/wandb/sdk/internal/internal_api.py", line 1036, in sweep
    raise ValueError(f"Sweep {entity}/{project}/{sweep} not found")
ValueError: Sweep ravid-d/NLP2024_PROJECT_RavidDimant/7vmhyl5a not found

During handling of the above exception, another exception occurred:

Traceback (most recent call last):
  File "/anaconda/envs/final_project_env/lib/python3.8/site-packages/wandb/cli/cli.py", line 108, in wrapper
    return func(*args, **kwargs)
  File "/anaconda/envs/final_project_env/lib/python3.8/site-packages/wandb/cli/cli.py", line 1806, in agent
    wandb_agent.agent(sweep_id, entity=entity, project=project, count=count)
  File "/anaconda/envs/final_project_env/lib/python3.8/site-packages/wandb/wandb_agent.py", line 570, in agent
    return run_agent(
  File "/anaconda/envs/final_project_env/lib/python3.8/site-packages/wandb/wandb_agent.py", line 528, in run_agent
    agent.run()
  File "/anaconda/envs/final_project_env/lib/python3.8/site-packages/wandb/wandb_agent.py", line 190, in run
    sweep_obj = self._api.sweep(self._sweep_id, "{}")
  File "/anaconda/envs/final_project_env/lib/python3.8/site-packages/wandb/apis/internal.py", line 126, in sweep
    return self.api.sweep(*args, **kwargs)
  File "/anaconda/envs/final_project_env/lib/python3.8/site-packages/wandb/apis/normalize.py", line 87, in wrapper
    raise CommError(message, err).with_traceback(sys.exc_info()[2])
  File "/anaconda/envs/final_project_env/lib/python3.8/site-packages/wandb/apis/normalize.py", line 41, in wrapper
    return func(*args, **kwargs)
  File "/anaconda/envs/final_project_env/lib/python3.8/site-packages/wandb/sdk/internal/internal_api.py", line 1036, in sweep
    raise ValueError(f"Sweep {entity}/{project}/{sweep} not found")
wandb.errors.CommError: Sweep ravid-d/NLP2024_PROJECT_RavidDimant/7vmhyl5a not found

2024-06-11 13:48:35 ERROR Traceback (most recent call last):
  File "/anaconda/envs/final_project_env/lib/python3.8/site-packages/wandb/apis/normalize.py", line 41, in wrapper
    return func(*args, **kwargs)
  File "/anaconda/envs/final_project_env/lib/python3.8/site-packages/wandb/sdk/internal/internal_api.py", line 1036, in sweep
    raise ValueError(f"Sweep {entity}/{project}/{sweep} not found")
ValueError: Sweep ravid-d/NLP2024_PROJECT_RavidDimant/7vmhyl5a not found

During handling of the above exception, another exception occurred:

Traceback (most recent call last):
  File "/anaconda/envs/final_project_env/lib/python3.8/site-packages/wandb/cli/cli.py", line 108, in wrapper
    return func(*args, **kwargs)
  File "/anaconda/envs/final_project_env/lib/python3.8/site-packages/wandb/cli/cli.py", line 1806, in agent
    wandb_agent.agent(sweep_id, entity=entity, project=project, count=count)
  File "/anaconda/envs/final_project_env/lib/python3.8/site-packages/wandb/wandb_agent.py", line 570, in agent
    return run_agent(
  File "/anaconda/envs/final_project_env/lib/python3.8/site-packages/wandb/wandb_agent.py", line 528, in run_agent
    agent.run()
  File "/anaconda/envs/final_project_env/lib/python3.8/site-packages/wandb/wandb_agent.py", line 190, in run
    sweep_obj = self._api.sweep(self._sweep_id, "{}")
  File "/anaconda/envs/final_project_env/lib/python3.8/site-packages/wandb/apis/internal.py", line 126, in sweep
    return self.api.sweep(*args, **kwargs)
  File "/anaconda/envs/final_project_env/lib/python3.8/site-packages/wandb/apis/normalize.py", line 87, in wrapper
    raise CommError(message, err).with_traceback(sys.exc_info()[2])
  File "/anaconda/envs/final_project_env/lib/python3.8/site-packages/wandb/apis/normalize.py", line 41, in wrapper
    return func(*args, **kwargs)
  File "/anaconda/envs/final_project_env/lib/python3.8/site-packages/wandb/sdk/internal/internal_api.py", line 1036, in sweep
    raise ValueError(f"Sweep {entity}/{project}/{sweep} not found")
wandb.errors.CommError: Sweep ravid-d/NLP2024_PROJECT_RavidDimant/7vmhyl5a not found

2024-06-11 13:48:36 ERROR Traceback (most recent call last):
  File "/anaconda/envs/final_project_env/lib/python3.8/site-packages/wandb/apis/normalize.py", line 41, in wrapper
    return func(*args, **kwargs)
  File "/anaconda/envs/final_project_env/lib/python3.8/site-packages/wandb/sdk/internal/internal_api.py", line 1036, in sweep
    raise ValueError(f"Sweep {entity}/{project}/{sweep} not found")
ValueError: Sweep ravid-d/NLP2024_PROJECT_RavidDimant/7vmhyl5a not found

During handling of the above exception, another exception occurred:

Traceback (most recent call last):
  File "/anaconda/envs/final_project_env/lib/python3.8/site-packages/wandb/cli/cli.py", line 108, in wrapper
    return func(*args, **kwargs)
  File "/anaconda/envs/final_project_env/lib/python3.8/site-packages/wandb/cli/cli.py", line 1806, in agent
    wandb_agent.agent(sweep_id, entity=entity, project=project, count=count)
  File "/anaconda/envs/final_project_env/lib/python3.8/site-packages/wandb/wandb_agent.py", line 570, in agent
    return run_agent(
  File "/anaconda/envs/final_project_env/lib/python3.8/site-packages/wandb/wandb_agent.py", line 528, in run_agent
    agent.run()
  File "/anaconda/envs/final_project_env/lib/python3.8/site-packages/wandb/wandb_agent.py", line 190, in run
    sweep_obj = self._api.sweep(self._sweep_id, "{}")
  File "/anaconda/envs/final_project_env/lib/python3.8/site-packages/wandb/apis/internal.py", line 126, in sweep
    return self.api.sweep(*args, **kwargs)
  File "/anaconda/envs/final_project_env/lib/python3.8/site-packages/wandb/apis/normalize.py", line 87, in wrapper
    raise CommError(message, err).with_traceback(sys.exc_info()[2])
  File "/anaconda/envs/final_project_env/lib/python3.8/site-packages/wandb/apis/normalize.py", line 41, in wrapper
    return func(*args, **kwargs)
  File "/anaconda/envs/final_project_env/lib/python3.8/site-packages/wandb/sdk/internal/internal_api.py", line 1036, in sweep
    raise ValueError(f"Sweep {entity}/{project}/{sweep} not found")
wandb.errors.CommError: Sweep ravid-d/NLP2024_PROJECT_RavidDimant/7vmhyl5a not found

2024-09-25 15:40:52 ERROR Traceback (most recent call last):
  File "/anaconda/envs/final_project_env/lib/python3.8/site-packages/wandb/apis/normalize.py", line 41, in wrapper
    return func(*args, **kwargs)
  File "/anaconda/envs/final_project_env/lib/python3.8/site-packages/wandb/sdk/internal/internal_api.py", line 1070, in sweep
    raise ValueError(f"Sweep {entity}/{project}/{sweep} not found")
ValueError: Sweep ravid-d/NLP2024_PROJECT_RavidDimant/aj4wohtm not found

During handling of the above exception, another exception occurred:

Traceback (most recent call last):
  File "/anaconda/envs/final_project_env/lib/python3.8/site-packages/wandb/cli/cli.py", line 108, in wrapper
    return func(*args, **kwargs)
  File "/anaconda/envs/final_project_env/lib/python3.8/site-packages/wandb/cli/cli.py", line 1849, in agent
    wandb_agent.agent(sweep_id, entity=entity, project=project, count=count)
  File "/anaconda/envs/final_project_env/lib/python3.8/site-packages/wandb/wandb_agent.py", line 572, in agent
    return run_agent(
  File "/anaconda/envs/final_project_env/lib/python3.8/site-packages/wandb/wandb_agent.py", line 530, in run_agent
    agent.run()
  File "/anaconda/envs/final_project_env/lib/python3.8/site-packages/wandb/wandb_agent.py", line 192, in run
    sweep_obj = self._api.sweep(self._sweep_id, "{}")
  File "/anaconda/envs/final_project_env/lib/python3.8/site-packages/wandb/apis/internal.py", line 130, in sweep
    return self.api.sweep(*args, **kwargs)
  File "/anaconda/envs/final_project_env/lib/python3.8/site-packages/wandb/apis/normalize.py", line 87, in wrapper
    raise CommError(message, err).with_traceback(sys.exc_info()[2])
  File "/anaconda/envs/final_project_env/lib/python3.8/site-packages/wandb/apis/normalize.py", line 41, in wrapper
    return func(*args, **kwargs)
  File "/anaconda/envs/final_project_env/lib/python3.8/site-packages/wandb/sdk/internal/internal_api.py", line 1070, in sweep
    raise ValueError(f"Sweep {entity}/{project}/{sweep} not found")
wandb.errors.CommError: Sweep ravid-d/NLP2024_PROJECT_RavidDimant/aj4wohtm not found

2024-09-25 15:44:18 ERROR Traceback (most recent call last):
  File "/anaconda/envs/final_project_env/lib/python3.8/site-packages/wandb/apis/normalize.py", line 41, in wrapper
    return func(*args, **kwargs)
  File "/anaconda/envs/final_project_env/lib/python3.8/site-packages/wandb/sdk/internal/internal_api.py", line 1070, in sweep
    raise ValueError(f"Sweep {entity}/{project}/{sweep} not found")
ValueError: Sweep ravid-d/NLP2024_PROJECT_RavidDimant/aj4wohtm not found

During handling of the above exception, another exception occurred:

Traceback (most recent call last):
  File "/anaconda/envs/final_project_env/lib/python3.8/site-packages/wandb/cli/cli.py", line 108, in wrapper
    return func(*args, **kwargs)
  File "/anaconda/envs/final_project_env/lib/python3.8/site-packages/wandb/cli/cli.py", line 1849, in agent
    wandb_agent.agent(sweep_id, entity=entity, project=project, count=count)
  File "/anaconda/envs/final_project_env/lib/python3.8/site-packages/wandb/wandb_agent.py", line 572, in agent
    return run_agent(
  File "/anaconda/envs/final_project_env/lib/python3.8/site-packages/wandb/wandb_agent.py", line 530, in run_agent
    agent.run()
  File "/anaconda/envs/final_project_env/lib/python3.8/site-packages/wandb/wandb_agent.py", line 192, in run
    sweep_obj = self._api.sweep(self._sweep_id, "{}")
  File "/anaconda/envs/final_project_env/lib/python3.8/site-packages/wandb/apis/internal.py", line 130, in sweep
    return self.api.sweep(*args, **kwargs)
  File "/anaconda/envs/final_project_env/lib/python3.8/site-packages/wandb/apis/normalize.py", line 87, in wrapper
    raise CommError(message, err).with_traceback(sys.exc_info()[2])
  File "/anaconda/envs/final_project_env/lib/python3.8/site-packages/wandb/apis/normalize.py", line 41, in wrapper
    return func(*args, **kwargs)
  File "/anaconda/envs/final_project_env/lib/python3.8/site-packages/wandb/sdk/internal/internal_api.py", line 1070, in sweep
    raise ValueError(f"Sweep {entity}/{project}/{sweep} not found")
wandb.errors.CommError: Sweep ravid-d/NLP2024_PROJECT_RavidDimant/aj4wohtm not found

2024-09-25 19:25:29 INFO Running runs: []
2024-09-25 19:25:29 INFO Agent received command: run
2024-09-25 19:25:29 INFO Agent starting run with config:
	ENV_HPT_mode: False
	bot_strategy_prob: 0
	online_simulation_factor: 0
	seed: 1
2024-09-25 19:25:29 INFO About to run command: python StrategyTransfer.py --ENV_HPT_mode=False --bot_strategy_prob=0 --online_simulation_factor=0 --seed=1
2024-09-25 19:25:34 INFO Running runs: ['n515vmn9']
2024-09-25 19:25:34 INFO Cleaning up finished run: n515vmn9
2024-09-25 19:25:35 INFO Agent received command: run
2024-09-25 19:25:35 INFO Agent starting run with config:
	ENV_HPT_mode: False
	bot_strategy_prob: 0
	online_simulation_factor: 0
	seed: 2
2024-09-25 19:25:35 INFO About to run command: python StrategyTransfer.py --ENV_HPT_mode=False --bot_strategy_prob=0 --online_simulation_factor=0 --seed=2
2024-09-25 19:25:40 INFO Running runs: ['2ofhofoj']
2024-09-25 19:25:40 INFO Cleaning up finished run: 2ofhofoj
2024-09-25 19:25:40 INFO Agent received command: run
2024-09-25 19:25:40 INFO Agent starting run with config:
	ENV_HPT_mode: False
	bot_strategy_prob: 0
	online_simulation_factor: 0
	seed: 3
2024-09-25 19:25:40 INFO About to run command: python StrategyTransfer.py --ENV_HPT_mode=False --bot_strategy_prob=0 --online_simulation_factor=0 --seed=3
2024-09-25 19:25:45 INFO Running runs: ['f15v8bu4']
2024-09-25 19:25:45 ERROR Detected 3 failed runs in the first 60 seconds, shutting down.
2024-09-25 19:25:45 INFO To disable this check set WANDB_AGENT_DISABLE_FLAPPING=true
2024-09-25 19:26:15 INFO Running runs: []
2024-09-25 19:26:15 INFO Agent received command: run
2024-09-25 19:26:15 INFO Agent starting run with config:
	ENV_HPT_mode: False
	bot_strategy_prob: 0
	online_simulation_factor: 0
	seed: 4
2024-09-25 19:26:15 INFO About to run command: python StrategyTransfer.py --ENV_HPT_mode=False --bot_strategy_prob=0 --online_simulation_factor=0 --seed=4
2024-09-25 19:26:20 INFO Running runs: ['qmtubjg7']
2024-09-25 19:26:20 INFO Cleaning up finished run: qmtubjg7
2024-09-25 19:26:20 INFO Agent received command: run
2024-09-25 19:26:20 INFO Agent starting run with config:
	ENV_HPT_mode: False
	bot_strategy_prob: 0
	online_simulation_factor: 0
	seed: 5
2024-09-25 19:26:20 INFO About to run command: python StrategyTransfer.py --ENV_HPT_mode=False --bot_strategy_prob=0 --online_simulation_factor=0 --seed=5
2024-09-25 19:26:25 INFO Running runs: ['vgq55zij']
2024-09-25 19:26:25 INFO Cleaning up finished run: vgq55zij
2024-09-25 19:26:26 INFO Agent received command: run
2024-09-25 19:26:26 INFO Agent starting run with config:
	ENV_HPT_mode: False
	bot_strategy_prob: 0
	online_simulation_factor: 4
	seed: 1
2024-09-25 19:26:26 INFO About to run command: python StrategyTransfer.py --ENV_HPT_mode=False --bot_strategy_prob=0 --online_simulation_factor=4 --seed=1
2024-09-25 19:26:31 INFO Running runs: ['6bsl64iw']
2024-09-25 19:26:31 ERROR Detected 3 failed runs in the first 60 seconds, shutting down.
2024-09-25 19:26:31 INFO To disable this check set WANDB_AGENT_DISABLE_FLAPPING=true
2024-09-28 19:36:53 INFO Running runs: []
2024-09-28 19:36:53 INFO Agent received command: run
2024-09-28 19:36:53 INFO Agent starting run with config:
	ENV_HPT_mode: False
	bot_strategy_prob: 0
	online_simulation_factor: 0
	seed: 1
2024-09-28 19:36:53 INFO About to run command: python StrategyTransfer.py --ENV_HPT_mode=False --bot_strategy_prob=0 --online_simulation_factor=0 --seed=1
2024-09-28 19:36:58 INFO Running runs: ['nypjffgw']
2024-09-28 19:36:58 INFO Cleaning up finished run: nypjffgw
2024-09-28 19:36:58 INFO Agent received command: run
2024-09-28 19:36:58 INFO Agent starting run with config:
	ENV_HPT_mode: False
	bot_strategy_prob: 0
	online_simulation_factor: 0
	seed: 2
2024-09-28 19:36:58 INFO About to run command: python StrategyTransfer.py --ENV_HPT_mode=False --bot_strategy_prob=0 --online_simulation_factor=0 --seed=2
2024-09-28 19:37:03 INFO Running runs: ['7o8y49ux']
2024-09-28 19:37:03 INFO Cleaning up finished run: 7o8y49ux
2024-09-28 19:37:04 INFO Agent received command: run
2024-09-28 19:37:04 INFO Agent starting run with config:
	ENV_HPT_mode: False
	bot_strategy_prob: 0
	online_simulation_factor: 0
	seed: 3
2024-09-28 19:37:04 INFO About to run command: python StrategyTransfer.py --ENV_HPT_mode=False --bot_strategy_prob=0 --online_simulation_factor=0 --seed=3
2024-09-28 19:37:09 INFO Running runs: ['huaco1bd']
2024-09-28 19:37:09 ERROR Detected 3 failed runs in the first 60 seconds, shutting down.
2024-09-28 19:37:09 INFO To disable this check set WANDB_AGENT_DISABLE_FLAPPING=true
2024-09-28 21:16:07 INFO Running runs: []
2024-09-28 21:16:07 INFO Agent received command: run
2024-09-28 21:16:07 INFO Agent starting run with config:
	ENV_HPT_mode: False
	bot_strategy_prob: 0
	online_simulation_factor: 0
	seed: 1
2024-09-28 21:16:07 INFO About to run command: python StrategyTransfer.py --ENV_HPT_mode=False --bot_strategy_prob=0 --online_simulation_factor=0 --seed=1
2024-09-28 21:16:12 INFO Running runs: ['nobj2q27']
2024-09-28 21:16:12 INFO Cleaning up finished run: nobj2q27
2024-09-28 21:16:13 INFO Agent received command: run
2024-09-28 21:16:13 INFO Agent starting run with config:
	ENV_HPT_mode: False
	bot_strategy_prob: 0
	online_simulation_factor: 0
	seed: 2
2024-09-28 21:16:13 INFO About to run command: python StrategyTransfer.py --ENV_HPT_mode=False --bot_strategy_prob=0 --online_simulation_factor=0 --seed=2
2024-09-28 21:16:13 INFO Running runs: []
2024-09-28 21:16:14 INFO Agent received command: run
2024-09-28 21:16:14 INFO Agent starting run with config:
	ENV_HPT_mode: False
	bot_strategy_prob: 0
	online_simulation_factor: 0
	seed: 3
2024-09-28 21:16:14 INFO About to run command: python StrategyTransfer.py --ENV_HPT_mode=False --bot_strategy_prob=0 --online_simulation_factor=0 --seed=3
2024-09-28 21:16:18 INFO Running runs: ['n6cbtl3k']
2024-09-28 21:16:18 INFO Cleaning up finished run: n6cbtl3k
2024-09-28 21:16:18 INFO Agent received command: run
2024-09-28 21:16:18 INFO Agent starting run with config:
	ENV_HPT_mode: False
	bot_strategy_prob: 0
	online_simulation_factor: 0
	seed: 4
2024-09-28 21:16:18 INFO About to run command: python StrategyTransfer.py --ENV_HPT_mode=False --bot_strategy_prob=0 --online_simulation_factor=0 --seed=4
2024-09-28 21:16:19 INFO Running runs: ['yrso1tg9']
2024-09-28 21:16:19 INFO Cleaning up finished run: yrso1tg9
2024-09-28 21:16:19 INFO Agent received command: run
2024-09-28 21:16:19 INFO Agent starting run with config:
	ENV_HPT_mode: False
	bot_strategy_prob: 0
	online_simulation_factor: 0
	seed: 5
2024-09-28 21:16:19 INFO About to run command: python StrategyTransfer.py --ENV_HPT_mode=False --bot_strategy_prob=0 --online_simulation_factor=0 --seed=5
2024-09-28 21:16:21 INFO Running runs: []
2024-09-28 21:16:22 INFO Agent received command: run
2024-09-28 21:16:22 INFO Agent starting run with config:
	ENV_HPT_mode: False
	bot_strategy_prob: 0
	online_simulation_factor: 4
	seed: 1
2024-09-28 21:16:22 INFO About to run command: python StrategyTransfer.py --ENV_HPT_mode=False --bot_strategy_prob=0 --online_simulation_factor=4 --seed=1
2024-09-28 21:16:23 INFO Running runs: ['se8tcdg1']
2024-09-28 21:16:23 ERROR Detected 3 failed runs in the first 60 seconds, shutting down.
2024-09-28 21:16:23 INFO To disable this check set WANDB_AGENT_DISABLE_FLAPPING=true
2024-09-28 21:16:24 INFO Running runs: ['7n83jyzc']
2024-09-28 21:16:24 INFO Cleaning up finished run: 7n83jyzc
2024-09-28 21:16:24 INFO Agent received command: run
2024-09-28 21:16:24 INFO Agent starting run with config:
	ENV_HPT_mode: False
	bot_strategy_prob: 0
	online_simulation_factor: 4
	seed: 2
2024-09-28 21:16:24 INFO About to run command: python StrategyTransfer.py --ENV_HPT_mode=False --bot_strategy_prob=0 --online_simulation_factor=4 --seed=2
2024-09-28 21:16:27 INFO Running runs: ['mfwkhsuc']
2024-09-28 21:16:27 INFO Cleaning up finished run: mfwkhsuc
2024-09-28 21:16:27 INFO Agent received command: run
2024-09-28 21:16:27 INFO Agent starting run with config:
	ENV_HPT_mode: False
	bot_strategy_prob: 0
	online_simulation_factor: 4
	seed: 3
2024-09-28 21:16:27 INFO About to run command: python StrategyTransfer.py --ENV_HPT_mode=False --bot_strategy_prob=0 --online_simulation_factor=4 --seed=3
2024-09-28 21:16:29 INFO Running runs: ['bhnshpcl']
2024-09-28 21:16:29 ERROR Detected 3 failed runs in the first 60 seconds, shutting down.
2024-09-28 21:16:29 INFO To disable this check set WANDB_AGENT_DISABLE_FLAPPING=true
2024-09-28 21:16:32 INFO Running runs: ['v81mimko']
2024-09-28 21:16:32 INFO Cleaning up finished run: v81mimko
2024-09-28 21:16:32 INFO Agent received command: run
2024-09-28 21:16:32 INFO Agent starting run with config:
	ENV_HPT_mode: False
	bot_strategy_prob: 0
	online_simulation_factor: 4
	seed: 4
2024-09-28 21:16:32 INFO About to run command: python StrategyTransfer.py --ENV_HPT_mode=False --bot_strategy_prob=0 --online_simulation_factor=4 --seed=4
2024-09-28 21:16:37 INFO Running runs: ['i9lb8lko']
2024-09-28 21:16:37 ERROR Detected 3 failed runs in the first 60 seconds, shutting down.
2024-09-28 21:16:37 INFO To disable this check set WANDB_AGENT_DISABLE_FLAPPING=true
2024-09-28 21:16:38 INFO Running runs: []
2024-09-28 21:16:38 INFO Agent received command: run
2024-09-28 21:16:38 INFO Agent starting run with config:
	ENV_HPT_mode: False
	bot_strategy_prob: 0
	online_simulation_factor: 4
	seed: 5
2024-09-28 21:16:38 INFO About to run command: python StrategyTransfer.py --ENV_HPT_mode=False --bot_strategy_prob=0 --online_simulation_factor=4 --seed=5
2024-09-28 21:16:43 INFO Running runs: ['2rbaw3gd']
2024-09-28 21:16:43 INFO Cleaning up finished run: 2rbaw3gd
2024-09-28 21:16:44 INFO Agent received command: run
2024-09-28 21:16:44 INFO Agent starting run with config:
	ENV_HPT_mode: False
	bot_strategy_prob: 0.25
	online_simulation_factor: 0
	seed: 1
2024-09-28 21:16:44 INFO About to run command: python StrategyTransfer.py --ENV_HPT_mode=False --bot_strategy_prob=0.25 --online_simulation_factor=0 --seed=1
2024-09-28 21:16:46 INFO Running runs: []
2024-09-28 21:16:46 INFO Agent received command: run
2024-09-28 21:16:46 INFO Agent starting run with config:
	ENV_HPT_mode: False
	bot_strategy_prob: 0.25
	online_simulation_factor: 0
	seed: 2
2024-09-28 21:16:46 INFO About to run command: python StrategyTransfer.py --ENV_HPT_mode=False --bot_strategy_prob=0.25 --online_simulation_factor=0 --seed=2
2024-09-28 21:16:49 INFO Running runs: ['2aklrpd8']
2024-09-28 21:16:49 INFO Cleaning up finished run: 2aklrpd8
2024-09-28 21:16:49 INFO Agent received command: run
2024-09-28 21:16:49 INFO Agent starting run with config:
	ENV_HPT_mode: False
	bot_strategy_prob: 0.25
	online_simulation_factor: 0
	seed: 3
2024-09-28 21:16:49 INFO About to run command: python StrategyTransfer.py --ENV_HPT_mode=False --bot_strategy_prob=0.25 --online_simulation_factor=0 --seed=3
2024-09-28 21:16:51 INFO Running runs: ['0u5r34n7']
2024-09-28 21:16:51 INFO Cleaning up finished run: 0u5r34n7
2024-09-28 21:16:51 INFO Running runs: []
2024-09-28 21:16:52 INFO Agent received command: run
2024-09-28 21:16:52 INFO Agent starting run with config:
	ENV_HPT_mode: False
	bot_strategy_prob: 0.25
	online_simulation_factor: 0
	seed: 4
2024-09-28 21:16:52 INFO About to run command: python StrategyTransfer.py --ENV_HPT_mode=False --bot_strategy_prob=0.25 --online_simulation_factor=0 --seed=4
2024-09-28 21:16:52 INFO Agent received command: run
2024-09-28 21:16:52 INFO Agent starting run with config:
	ENV_HPT_mode: False
	bot_strategy_prob: 0.25
	online_simulation_factor: 0
	seed: 5
2024-09-28 21:16:52 INFO About to run command: python StrategyTransfer.py --ENV_HPT_mode=False --bot_strategy_prob=0.25 --online_simulation_factor=0 --seed=5
2024-09-28 21:16:54 INFO Running runs: ['hlx259wl']
2024-09-28 21:16:54 ERROR Detected 3 failed runs in the first 60 seconds, shutting down.
2024-09-28 21:16:54 INFO To disable this check set WANDB_AGENT_DISABLE_FLAPPING=true
2024-09-28 21:16:57 INFO Running runs: ['o9u95n6l']
2024-09-28 21:16:57 INFO Cleaning up finished run: o9u95n6l
2024-09-28 21:16:57 INFO Running runs: ['c9w82v7m']
2024-09-28 21:16:57 INFO Cleaning up finished run: c9w82v7m
2024-09-28 21:16:57 INFO Agent received command: run
2024-09-28 21:16:57 INFO Agent starting run with config:
	ENV_HPT_mode: False
	bot_strategy_prob: 0.25
	online_simulation_factor: 4
	seed: 1
2024-09-28 21:16:57 INFO About to run command: python StrategyTransfer.py --ENV_HPT_mode=False --bot_strategy_prob=0.25 --online_simulation_factor=4 --seed=1
2024-09-28 21:16:57 INFO Agent received command: run
2024-09-28 21:16:57 INFO Agent starting run with config:
	ENV_HPT_mode: False
	bot_strategy_prob: 0.25
	online_simulation_factor: 4
	seed: 2
2024-09-28 21:16:57 INFO About to run command: python StrategyTransfer.py --ENV_HPT_mode=False --bot_strategy_prob=0.25 --online_simulation_factor=4 --seed=2
2024-09-28 21:17:02 INFO Running runs: ['5yjou326']
2024-09-28 21:17:02 INFO Cleaning up finished run: 5yjou326
2024-09-28 21:17:02 INFO Running runs: ['6fv87g5w']
2024-09-28 21:17:02 ERROR Detected 3 failed runs in the first 60 seconds, shutting down.
2024-09-28 21:17:02 INFO To disable this check set WANDB_AGENT_DISABLE_FLAPPING=true
2024-09-28 21:17:02 INFO Agent received command: run
2024-09-28 21:17:02 INFO Agent starting run with config:
	ENV_HPT_mode: False
	bot_strategy_prob: 0.25
	online_simulation_factor: 4
	seed: 3
2024-09-28 21:17:02 INFO About to run command: python StrategyTransfer.py --ENV_HPT_mode=False --bot_strategy_prob=0.25 --online_simulation_factor=4 --seed=3
2024-09-28 21:17:07 INFO Running runs: ['6r25vr1i']
2024-09-28 21:17:07 ERROR Detected 3 failed runs in the first 60 seconds, shutting down.
2024-09-28 21:17:07 INFO To disable this check set WANDB_AGENT_DISABLE_FLAPPING=true
2024-09-28 21:50:29 INFO Running runs: []
2024-09-28 21:50:29 INFO Agent received command: run
2024-09-28 21:50:29 INFO Agent starting run with config:
	ENV_HPT_mode: False
	bot_strategy_prob: 0
	online_simulation_factor: 0
	seed: 1
2024-09-28 21:50:29 INFO About to run command: python StrategyTransfer.py --ENV_HPT_mode=False --bot_strategy_prob=0 --online_simulation_factor=0 --seed=1
2024-09-28 21:50:34 INFO Running runs: ['gst453ir']
2024-09-28 21:50:34 INFO Cleaning up finished run: gst453ir
2024-09-28 21:50:35 INFO Running runs: []
2024-09-28 21:50:35 INFO Agent received command: run
2024-09-28 21:50:35 INFO Agent starting run with config:
	ENV_HPT_mode: False
	bot_strategy_prob: 0
	online_simulation_factor: 0
	seed: 2
2024-09-28 21:50:35 INFO About to run command: python StrategyTransfer.py --ENV_HPT_mode=False --bot_strategy_prob=0 --online_simulation_factor=0 --seed=2
2024-09-28 21:50:35 INFO Agent received command: run
2024-09-28 21:50:35 INFO Agent starting run with config:
	ENV_HPT_mode: False
	bot_strategy_prob: 0
	online_simulation_factor: 0
	seed: 3
2024-09-28 21:50:35 INFO About to run command: python StrategyTransfer.py --ENV_HPT_mode=False --bot_strategy_prob=0 --online_simulation_factor=0 --seed=3
2024-09-28 21:50:40 INFO Running runs: ['yr7p0i9g']
2024-09-28 21:50:40 INFO Cleaning up finished run: yr7p0i9g
2024-09-28 21:50:40 INFO Running runs: ['x9skftm7']
2024-09-28 21:50:40 INFO Cleaning up finished run: x9skftm7
2024-09-28 21:50:40 INFO Agent received command: run
2024-09-28 21:50:40 INFO Agent starting run with config:
	ENV_HPT_mode: False
	bot_strategy_prob: 0
	online_simulation_factor: 0
	seed: 4
2024-09-28 21:50:40 INFO About to run command: python StrategyTransfer.py --ENV_HPT_mode=False --bot_strategy_prob=0 --online_simulation_factor=0 --seed=4
2024-09-28 21:50:40 INFO Agent received command: run
2024-09-28 21:50:40 INFO Agent starting run with config:
	ENV_HPT_mode: False
	bot_strategy_prob: 0
	online_simulation_factor: 0
	seed: 5
2024-09-28 21:50:40 INFO About to run command: python StrategyTransfer.py --ENV_HPT_mode=False --bot_strategy_prob=0 --online_simulation_factor=0 --seed=5
2024-09-28 21:50:41 INFO Running runs: []
2024-09-28 21:50:41 INFO Agent received command: run
2024-09-28 21:50:41 INFO Agent starting run with config:
	ENV_HPT_mode: False
	bot_strategy_prob: 0
	online_simulation_factor: 4
	seed: 1
2024-09-28 21:50:41 INFO About to run command: python StrategyTransfer.py --ENV_HPT_mode=False --bot_strategy_prob=0 --online_simulation_factor=4 --seed=1
2024-09-28 21:50:45 INFO Running runs: ['lgbjt8yd']
2024-09-28 21:50:45 ERROR Detected 3 failed runs in the first 60 seconds, shutting down.
2024-09-28 21:50:45 INFO To disable this check set WANDB_AGENT_DISABLE_FLAPPING=true
2024-09-28 21:50:45 INFO Running runs: ['xg3nx2oi']
2024-09-28 21:50:45 INFO Cleaning up finished run: xg3nx2oi
2024-09-28 21:50:46 INFO Agent received command: run
2024-09-28 21:50:46 INFO Agent starting run with config:
	ENV_HPT_mode: False
	bot_strategy_prob: 0
	online_simulation_factor: 4
	seed: 2
2024-09-28 21:50:46 INFO About to run command: python StrategyTransfer.py --ENV_HPT_mode=False --bot_strategy_prob=0 --online_simulation_factor=4 --seed=2
2024-09-28 21:50:46 INFO Running runs: ['lmai6oz8']
2024-09-28 21:50:46 INFO Cleaning up finished run: lmai6oz8
2024-09-28 21:50:47 INFO Agent received command: run
2024-09-28 21:50:47 INFO Agent starting run with config:
	ENV_HPT_mode: False
	bot_strategy_prob: 0
	online_simulation_factor: 4
	seed: 3
2024-09-28 21:50:47 INFO About to run command: python StrategyTransfer.py --ENV_HPT_mode=False --bot_strategy_prob=0 --online_simulation_factor=4 --seed=3
2024-09-28 21:50:49 INFO Running runs: []
2024-09-28 21:50:49 INFO Agent received command: run
2024-09-28 21:50:49 INFO Agent starting run with config:
	ENV_HPT_mode: False
	bot_strategy_prob: 0
	online_simulation_factor: 4
	seed: 4
2024-09-28 21:50:49 INFO About to run command: python StrategyTransfer.py --ENV_HPT_mode=False --bot_strategy_prob=0 --online_simulation_factor=4 --seed=4
2024-09-28 21:50:51 INFO Running runs: ['kj7zk7xc']
2024-09-28 21:50:51 ERROR Detected 3 failed runs in the first 60 seconds, shutting down.
2024-09-28 21:50:51 INFO To disable this check set WANDB_AGENT_DISABLE_FLAPPING=true
2024-09-28 21:50:52 INFO Running runs: ['zdn38odo']
2024-09-28 21:50:52 INFO Cleaning up finished run: zdn38odo
2024-09-28 21:50:52 INFO Agent received command: run
2024-09-28 21:50:52 INFO Agent starting run with config:
	ENV_HPT_mode: False
	bot_strategy_prob: 0
	online_simulation_factor: 4
	seed: 5
2024-09-28 21:50:52 INFO About to run command: python StrategyTransfer.py --ENV_HPT_mode=False --bot_strategy_prob=0 --online_simulation_factor=4 --seed=5
2024-09-28 21:50:54 INFO Running runs: ['ujlmb97c']
2024-09-28 21:50:54 INFO Cleaning up finished run: ujlmb97c
2024-09-28 21:50:55 INFO Agent received command: run
2024-09-28 21:50:55 INFO Agent starting run with config:
	ENV_HPT_mode: False
	bot_strategy_prob: 0.25
	online_simulation_factor: 0
	seed: 1
2024-09-28 21:50:55 INFO About to run command: python StrategyTransfer.py --ENV_HPT_mode=False --bot_strategy_prob=0.25 --online_simulation_factor=0 --seed=1
2024-09-28 21:50:57 INFO Running runs: []
2024-09-28 21:50:57 INFO Running runs: ['sceqpmu1']
2024-09-28 21:50:57 ERROR Detected 3 failed runs in the first 60 seconds, shutting down.
2024-09-28 21:50:57 INFO To disable this check set WANDB_AGENT_DISABLE_FLAPPING=true
2024-09-28 21:50:57 INFO Agent received command: run
2024-09-28 21:50:57 INFO Agent starting run with config:
	ENV_HPT_mode: False
	bot_strategy_prob: 0.25
	online_simulation_factor: 0
	seed: 2
2024-09-28 21:50:57 INFO About to run command: python StrategyTransfer.py --ENV_HPT_mode=False --bot_strategy_prob=0.25 --online_simulation_factor=0 --seed=2
2024-09-28 21:51:00 INFO Running runs: ['7glxlc85']
2024-09-28 21:51:00 INFO Cleaning up finished run: 7glxlc85
2024-09-28 21:51:01 INFO Agent received command: run
2024-09-28 21:51:01 INFO Agent starting run with config:
	ENV_HPT_mode: False
	bot_strategy_prob: 0.25
	online_simulation_factor: 0
	seed: 3
2024-09-28 21:51:01 INFO About to run command: python StrategyTransfer.py --ENV_HPT_mode=False --bot_strategy_prob=0.25 --online_simulation_factor=0 --seed=3
2024-09-28 21:51:02 INFO Running runs: ['a6q5gpyl']
2024-09-28 21:51:02 INFO Cleaning up finished run: a6q5gpyl
2024-09-28 21:51:03 INFO Agent received command: run
2024-09-28 21:51:03 INFO Agent starting run with config:
	ENV_HPT_mode: False
	bot_strategy_prob: 0.25
	online_simulation_factor: 0
	seed: 4
2024-09-28 21:51:03 INFO About to run command: python StrategyTransfer.py --ENV_HPT_mode=False --bot_strategy_prob=0.25 --online_simulation_factor=0 --seed=4
2024-09-28 21:51:04 INFO Running runs: []
2024-09-28 21:51:04 INFO Agent received command: run
2024-09-28 21:51:04 INFO Agent starting run with config:
	ENV_HPT_mode: False
	bot_strategy_prob: 0.25
	online_simulation_factor: 0
	seed: 5
2024-09-28 21:51:04 INFO About to run command: python StrategyTransfer.py --ENV_HPT_mode=False --bot_strategy_prob=0.25 --online_simulation_factor=0 --seed=5
2024-09-28 21:51:06 INFO Running runs: ['1x0dg6k6']
2024-09-28 21:51:06 ERROR Detected 3 failed runs in the first 60 seconds, shutting down.
2024-09-28 21:51:06 INFO To disable this check set WANDB_AGENT_DISABLE_FLAPPING=true
2024-09-28 21:51:08 INFO Running runs: ['jp301953']
2024-09-28 21:51:08 INFO Cleaning up finished run: jp301953
2024-09-28 21:51:08 INFO Agent received command: run
2024-09-28 21:51:08 INFO Agent starting run with config:
	ENV_HPT_mode: False
	bot_strategy_prob: 0.25
	online_simulation_factor: 4
	seed: 1
2024-09-28 21:51:08 INFO About to run command: python StrategyTransfer.py --ENV_HPT_mode=False --bot_strategy_prob=0.25 --online_simulation_factor=4 --seed=1
2024-09-28 21:51:09 INFO Running runs: ['yjfoe9ee']
2024-09-28 21:51:09 INFO Cleaning up finished run: yjfoe9ee
2024-09-28 21:51:10 INFO Agent received command: run
2024-09-28 21:51:10 INFO Agent starting run with config:
	ENV_HPT_mode: False
	bot_strategy_prob: 0.25
	online_simulation_factor: 4
	seed: 2
2024-09-28 21:51:10 INFO About to run command: python StrategyTransfer.py --ENV_HPT_mode=False --bot_strategy_prob=0.25 --online_simulation_factor=4 --seed=2
2024-09-28 21:51:13 INFO Running runs: ['9093p3cf']
2024-09-28 21:51:13 ERROR Detected 3 failed runs in the first 60 seconds, shutting down.
2024-09-28 21:51:13 INFO To disable this check set WANDB_AGENT_DISABLE_FLAPPING=true
2024-09-28 21:51:15 INFO Running runs: ['bqe190sr']
2024-09-28 21:51:15 INFO Cleaning up finished run: bqe190sr
2024-09-28 21:51:16 INFO Agent received command: run
2024-09-28 21:51:16 INFO Agent starting run with config:
	ENV_HPT_mode: False
	bot_strategy_prob: 0.25
	online_simulation_factor: 4
	seed: 3
2024-09-28 21:51:16 INFO About to run command: python StrategyTransfer.py --ENV_HPT_mode=False --bot_strategy_prob=0.25 --online_simulation_factor=4 --seed=3
2024-09-28 21:51:21 INFO Running runs: ['89fydwek']
2024-09-28 21:51:21 ERROR Detected 3 failed runs in the first 60 seconds, shutting down.
2024-09-28 21:51:21 INFO To disable this check set WANDB_AGENT_DISABLE_FLAPPING=true
2024-09-29 12:29:44 ERROR Traceback (most recent call last):
  File "/anaconda/envs/final_project_env/lib/python3.8/site-packages/wandb/apis/normalize.py", line 41, in wrapper
    return func(*args, **kwargs)
  File "/anaconda/envs/final_project_env/lib/python3.8/site-packages/wandb/sdk/internal/internal_api.py", line 1077, in sweep
    raise ValueError(f"Sweep {entity}/{project}/{sweep} not found")
ValueError: Sweep ravid-d/NLP2024_PROJECT_RavidDimant/cr8zcg71 not found

During handling of the above exception, another exception occurred:

Traceback (most recent call last):
  File "/anaconda/envs/final_project_env/lib/python3.8/site-packages/wandb/cli/cli.py", line 108, in wrapper
    return func(*args, **kwargs)
  File "/anaconda/envs/final_project_env/lib/python3.8/site-packages/wandb/cli/cli.py", line 1846, in agent
    wandb_agent.agent(sweep_id, entity=entity, project=project, count=count)
  File "/anaconda/envs/final_project_env/lib/python3.8/site-packages/wandb/wandb_agent.py", line 572, in agent
    return run_agent(
  File "/anaconda/envs/final_project_env/lib/python3.8/site-packages/wandb/wandb_agent.py", line 530, in run_agent
    agent.run()
  File "/anaconda/envs/final_project_env/lib/python3.8/site-packages/wandb/wandb_agent.py", line 192, in run
    sweep_obj = self._api.sweep(self._sweep_id, "{}")
  File "/anaconda/envs/final_project_env/lib/python3.8/site-packages/wandb/apis/internal.py", line 130, in sweep
    return self.api.sweep(*args, **kwargs)
  File "/anaconda/envs/final_project_env/lib/python3.8/site-packages/wandb/apis/normalize.py", line 87, in wrapper
    raise CommError(message, err).with_traceback(sys.exc_info()[2])
  File "/anaconda/envs/final_project_env/lib/python3.8/site-packages/wandb/apis/normalize.py", line 41, in wrapper
    return func(*args, **kwargs)
  File "/anaconda/envs/final_project_env/lib/python3.8/site-packages/wandb/sdk/internal/internal_api.py", line 1077, in sweep
    raise ValueError(f"Sweep {entity}/{project}/{sweep} not found")
wandb.errors.errors.CommError: Sweep ravid-d/NLP2024_PROJECT_RavidDimant/cr8zcg71 not found

2024-09-29 12:29:48 ERROR Traceback (most recent call last):
  File "/anaconda/envs/final_project_env/lib/python3.8/site-packages/wandb/apis/normalize.py", line 41, in wrapper
    return func(*args, **kwargs)
  File "/anaconda/envs/final_project_env/lib/python3.8/site-packages/wandb/sdk/internal/internal_api.py", line 1077, in sweep
    raise ValueError(f"Sweep {entity}/{project}/{sweep} not found")
ValueError: Sweep ravid-d/NLP2024_PROJECT_RavidDimant/cr8zcg71 not found

During handling of the above exception, another exception occurred:

Traceback (most recent call last):
  File "/anaconda/envs/final_project_env/lib/python3.8/site-packages/wandb/cli/cli.py", line 108, in wrapper
    return func(*args, **kwargs)
  File "/anaconda/envs/final_project_env/lib/python3.8/site-packages/wandb/cli/cli.py", line 1846, in agent
    wandb_agent.agent(sweep_id, entity=entity, project=project, count=count)
  File "/anaconda/envs/final_project_env/lib/python3.8/site-packages/wandb/wandb_agent.py", line 572, in agent
    return run_agent(
  File "/anaconda/envs/final_project_env/lib/python3.8/site-packages/wandb/wandb_agent.py", line 530, in run_agent
    agent.run()
  File "/anaconda/envs/final_project_env/lib/python3.8/site-packages/wandb/wandb_agent.py", line 192, in run
    sweep_obj = self._api.sweep(self._sweep_id, "{}")
  File "/anaconda/envs/final_project_env/lib/python3.8/site-packages/wandb/apis/internal.py", line 130, in sweep
    return self.api.sweep(*args, **kwargs)
  File "/anaconda/envs/final_project_env/lib/python3.8/site-packages/wandb/apis/normalize.py", line 87, in wrapper
    raise CommError(message, err).with_traceback(sys.exc_info()[2])
  File "/anaconda/envs/final_project_env/lib/python3.8/site-packages/wandb/apis/normalize.py", line 41, in wrapper
    return func(*args, **kwargs)
  File "/anaconda/envs/final_project_env/lib/python3.8/site-packages/wandb/sdk/internal/internal_api.py", line 1077, in sweep
    raise ValueError(f"Sweep {entity}/{project}/{sweep} not found")
wandb.errors.errors.CommError: Sweep ravid-d/NLP2024_PROJECT_RavidDimant/cr8zcg71 not found

2024-09-29 12:29:57 ERROR Traceback (most recent call last):
  File "/anaconda/envs/final_project_env/lib/python3.8/site-packages/wandb/apis/normalize.py", line 41, in wrapper
    return func(*args, **kwargs)
  File "/anaconda/envs/final_project_env/lib/python3.8/site-packages/wandb/sdk/internal/internal_api.py", line 1077, in sweep
    raise ValueError(f"Sweep {entity}/{project}/{sweep} not found")
ValueError: Sweep ravid-d/NLP2024_PROJECT_RavidDimant/cr8zcg71 not found

During handling of the above exception, another exception occurred:

Traceback (most recent call last):
  File "/anaconda/envs/final_project_env/lib/python3.8/site-packages/wandb/cli/cli.py", line 108, in wrapper
    return func(*args, **kwargs)
  File "/anaconda/envs/final_project_env/lib/python3.8/site-packages/wandb/cli/cli.py", line 1846, in agent
    wandb_agent.agent(sweep_id, entity=entity, project=project, count=count)
  File "/anaconda/envs/final_project_env/lib/python3.8/site-packages/wandb/wandb_agent.py", line 572, in agent
    return run_agent(
  File "/anaconda/envs/final_project_env/lib/python3.8/site-packages/wandb/wandb_agent.py", line 530, in run_agent
    agent.run()
  File "/anaconda/envs/final_project_env/lib/python3.8/site-packages/wandb/wandb_agent.py", line 192, in run
    sweep_obj = self._api.sweep(self._sweep_id, "{}")
  File "/anaconda/envs/final_project_env/lib/python3.8/site-packages/wandb/apis/internal.py", line 130, in sweep
    return self.api.sweep(*args, **kwargs)
  File "/anaconda/envs/final_project_env/lib/python3.8/site-packages/wandb/apis/normalize.py", line 87, in wrapper
    raise CommError(message, err).with_traceback(sys.exc_info()[2])
  File "/anaconda/envs/final_project_env/lib/python3.8/site-packages/wandb/apis/normalize.py", line 41, in wrapper
    return func(*args, **kwargs)
  File "/anaconda/envs/final_project_env/lib/python3.8/site-packages/wandb/sdk/internal/internal_api.py", line 1077, in sweep
    raise ValueError(f"Sweep {entity}/{project}/{sweep} not found")
wandb.errors.errors.CommError: Sweep ravid-d/NLP2024_PROJECT_RavidDimant/cr8zcg71 not found

2024-09-29 12:30:04 ERROR Traceback (most recent call last):
  File "/anaconda/envs/final_project_env/lib/python3.8/site-packages/wandb/apis/normalize.py", line 41, in wrapper
    return func(*args, **kwargs)
  File "/anaconda/envs/final_project_env/lib/python3.8/site-packages/wandb/sdk/internal/internal_api.py", line 1077, in sweep
    raise ValueError(f"Sweep {entity}/{project}/{sweep} not found")
ValueError: Sweep ravid-d/NLP2024_PROJECT_RavidDimant/cr8zcg71 not found

During handling of the above exception, another exception occurred:

Traceback (most recent call last):
  File "/anaconda/envs/final_project_env/lib/python3.8/site-packages/wandb/cli/cli.py", line 108, in wrapper
    return func(*args, **kwargs)
  File "/anaconda/envs/final_project_env/lib/python3.8/site-packages/wandb/cli/cli.py", line 1846, in agent
    wandb_agent.agent(sweep_id, entity=entity, project=project, count=count)
  File "/anaconda/envs/final_project_env/lib/python3.8/site-packages/wandb/wandb_agent.py", line 572, in agent
    return run_agent(
  File "/anaconda/envs/final_project_env/lib/python3.8/site-packages/wandb/wandb_agent.py", line 530, in run_agent
    agent.run()
  File "/anaconda/envs/final_project_env/lib/python3.8/site-packages/wandb/wandb_agent.py", line 192, in run
    sweep_obj = self._api.sweep(self._sweep_id, "{}")
  File "/anaconda/envs/final_project_env/lib/python3.8/site-packages/wandb/apis/internal.py", line 130, in sweep
    return self.api.sweep(*args, **kwargs)
  File "/anaconda/envs/final_project_env/lib/python3.8/site-packages/wandb/apis/normalize.py", line 87, in wrapper
    raise CommError(message, err).with_traceback(sys.exc_info()[2])
  File "/anaconda/envs/final_project_env/lib/python3.8/site-packages/wandb/apis/normalize.py", line 41, in wrapper
    return func(*args, **kwargs)
  File "/anaconda/envs/final_project_env/lib/python3.8/site-packages/wandb/sdk/internal/internal_api.py", line 1077, in sweep
    raise ValueError(f"Sweep {entity}/{project}/{sweep} not found")
wandb.errors.errors.CommError: Sweep ravid-d/NLP2024_PROJECT_RavidDimant/cr8zcg71 not found

2024-09-29 12:30:12 ERROR Traceback (most recent call last):
  File "/anaconda/envs/final_project_env/lib/python3.8/site-packages/wandb/apis/normalize.py", line 41, in wrapper
    return func(*args, **kwargs)
  File "/anaconda/envs/final_project_env/lib/python3.8/site-packages/wandb/sdk/internal/internal_api.py", line 1077, in sweep
    raise ValueError(f"Sweep {entity}/{project}/{sweep} not found")
ValueError: Sweep ravid-d/NLP2024_PROJECT_RavidDimant/cr8zcg71 not found

During handling of the above exception, another exception occurred:

Traceback (most recent call last):
  File "/anaconda/envs/final_project_env/lib/python3.8/site-packages/wandb/cli/cli.py", line 108, in wrapper
    return func(*args, **kwargs)
  File "/anaconda/envs/final_project_env/lib/python3.8/site-packages/wandb/cli/cli.py", line 1846, in agent
    wandb_agent.agent(sweep_id, entity=entity, project=project, count=count)
  File "/anaconda/envs/final_project_env/lib/python3.8/site-packages/wandb/wandb_agent.py", line 572, in agent
    return run_agent(
  File "/anaconda/envs/final_project_env/lib/python3.8/site-packages/wandb/wandb_agent.py", line 530, in run_agent
    agent.run()
  File "/anaconda/envs/final_project_env/lib/python3.8/site-packages/wandb/wandb_agent.py", line 192, in run
    sweep_obj = self._api.sweep(self._sweep_id, "{}")
  File "/anaconda/envs/final_project_env/lib/python3.8/site-packages/wandb/apis/internal.py", line 130, in sweep
    return self.api.sweep(*args, **kwargs)
  File "/anaconda/envs/final_project_env/lib/python3.8/site-packages/wandb/apis/normalize.py", line 87, in wrapper
    raise CommError(message, err).with_traceback(sys.exc_info()[2])
  File "/anaconda/envs/final_project_env/lib/python3.8/site-packages/wandb/apis/normalize.py", line 41, in wrapper
    return func(*args, **kwargs)
  File "/anaconda/envs/final_project_env/lib/python3.8/site-packages/wandb/sdk/internal/internal_api.py", line 1077, in sweep
    raise ValueError(f"Sweep {entity}/{project}/{sweep} not found")
wandb.errors.errors.CommError: Sweep ravid-d/NLP2024_PROJECT_RavidDimant/cr8zcg71 not found

2024-09-29 12:30:20 ERROR Traceback (most recent call last):
  File "/anaconda/envs/final_project_env/lib/python3.8/site-packages/wandb/apis/normalize.py", line 41, in wrapper
    return func(*args, **kwargs)
  File "/anaconda/envs/final_project_env/lib/python3.8/site-packages/wandb/sdk/internal/internal_api.py", line 1077, in sweep
    raise ValueError(f"Sweep {entity}/{project}/{sweep} not found")
ValueError: Sweep ravid-d/NLP2024_PROJECT_RavidDimant/cr8zcg71 not found

During handling of the above exception, another exception occurred:

Traceback (most recent call last):
  File "/anaconda/envs/final_project_env/lib/python3.8/site-packages/wandb/cli/cli.py", line 108, in wrapper
    return func(*args, **kwargs)
  File "/anaconda/envs/final_project_env/lib/python3.8/site-packages/wandb/cli/cli.py", line 1846, in agent
    wandb_agent.agent(sweep_id, entity=entity, project=project, count=count)
  File "/anaconda/envs/final_project_env/lib/python3.8/site-packages/wandb/wandb_agent.py", line 572, in agent
    return run_agent(
  File "/anaconda/envs/final_project_env/lib/python3.8/site-packages/wandb/wandb_agent.py", line 530, in run_agent
    agent.run()
  File "/anaconda/envs/final_project_env/lib/python3.8/site-packages/wandb/wandb_agent.py", line 192, in run
    sweep_obj = self._api.sweep(self._sweep_id, "{}")
  File "/anaconda/envs/final_project_env/lib/python3.8/site-packages/wandb/apis/internal.py", line 130, in sweep
    return self.api.sweep(*args, **kwargs)
  File "/anaconda/envs/final_project_env/lib/python3.8/site-packages/wandb/apis/normalize.py", line 87, in wrapper
    raise CommError(message, err).with_traceback(sys.exc_info()[2])
  File "/anaconda/envs/final_project_env/lib/python3.8/site-packages/wandb/apis/normalize.py", line 41, in wrapper
    return func(*args, **kwargs)
  File "/anaconda/envs/final_project_env/lib/python3.8/site-packages/wandb/sdk/internal/internal_api.py", line 1077, in sweep
    raise ValueError(f"Sweep {entity}/{project}/{sweep} not found")
wandb.errors.errors.CommError: Sweep ravid-d/NLP2024_PROJECT_RavidDimant/cr8zcg71 not found

2024-09-29 12:35:45 INFO Running runs: []
2024-09-29 12:35:46 INFO Agent received command: run
2024-09-29 12:35:46 INFO Agent starting run with config:
	ENV_HPT_mode: False
	bot_strategy_prob: 0
	seed: 1
2024-09-29 12:35:46 INFO About to run command: python StrategyTransfer.py --ENV_HPT_mode=False --bot_strategy_prob=0 --seed=1
2024-09-29 12:35:51 INFO Running runs: ['9rxuk7vf']
2024-09-29 12:35:51 INFO Cleaning up finished run: 9rxuk7vf
2024-09-29 12:35:51 INFO Agent received command: run
2024-09-29 12:35:51 INFO Agent starting run with config:
	ENV_HPT_mode: False
	bot_strategy_prob: 0
	seed: 2
2024-09-29 12:35:51 INFO About to run command: python StrategyTransfer.py --ENV_HPT_mode=False --bot_strategy_prob=0 --seed=2
2024-09-29 12:35:56 INFO Running runs: ['b9il9b7y']
2024-09-29 12:35:56 INFO Cleaning up finished run: b9il9b7y
2024-09-29 12:35:56 INFO Agent received command: run
2024-09-29 12:35:56 INFO Agent starting run with config:
	ENV_HPT_mode: False
	bot_strategy_prob: 0
	seed: 3
2024-09-29 12:35:56 INFO About to run command: python StrategyTransfer.py --ENV_HPT_mode=False --bot_strategy_prob=0 --seed=3
2024-09-29 12:36:01 INFO Running runs: ['eimlapfg']
2024-09-29 12:36:01 ERROR Detected 3 failed runs in the first 60 seconds, shutting down.
2024-09-29 12:36:01 INFO To disable this check set WANDB_AGENT_DISABLE_FLAPPING=true
2024-09-29 13:00:10 ERROR Traceback (most recent call last):
  File "/anaconda/envs/final_project_env/lib/python3.8/site-packages/wandb/apis/normalize.py", line 41, in wrapper
    return func(*args, **kwargs)
  File "/anaconda/envs/final_project_env/lib/python3.8/site-packages/wandb/sdk/internal/internal_api.py", line 1077, in sweep
    raise ValueError(f"Sweep {entity}/{project}/{sweep} not found")
ValueError: Sweep ravid-d/NLP2024_PROJECT_RavidDimant/zv3h8t0y not found

During handling of the above exception, another exception occurred:

Traceback (most recent call last):
  File "/anaconda/envs/final_project_env/lib/python3.8/site-packages/wandb/cli/cli.py", line 108, in wrapper
    return func(*args, **kwargs)
  File "/anaconda/envs/final_project_env/lib/python3.8/site-packages/wandb/cli/cli.py", line 1846, in agent
    wandb_agent.agent(sweep_id, entity=entity, project=project, count=count)
  File "/anaconda/envs/final_project_env/lib/python3.8/site-packages/wandb/wandb_agent.py", line 572, in agent
    return run_agent(
  File "/anaconda/envs/final_project_env/lib/python3.8/site-packages/wandb/wandb_agent.py", line 530, in run_agent
    agent.run()
  File "/anaconda/envs/final_project_env/lib/python3.8/site-packages/wandb/wandb_agent.py", line 192, in run
    sweep_obj = self._api.sweep(self._sweep_id, "{}")
  File "/anaconda/envs/final_project_env/lib/python3.8/site-packages/wandb/apis/internal.py", line 130, in sweep
    return self.api.sweep(*args, **kwargs)
  File "/anaconda/envs/final_project_env/lib/python3.8/site-packages/wandb/apis/normalize.py", line 87, in wrapper
    raise CommError(message, err).with_traceback(sys.exc_info()[2])
  File "/anaconda/envs/final_project_env/lib/python3.8/site-packages/wandb/apis/normalize.py", line 41, in wrapper
    return func(*args, **kwargs)
  File "/anaconda/envs/final_project_env/lib/python3.8/site-packages/wandb/sdk/internal/internal_api.py", line 1077, in sweep
    raise ValueError(f"Sweep {entity}/{project}/{sweep} not found")
wandb.errors.errors.CommError: Sweep ravid-d/NLP2024_PROJECT_RavidDimant/zv3h8t0y not found

2024-09-29 13:00:14 ERROR Traceback (most recent call last):
  File "/anaconda/envs/final_project_env/lib/python3.8/site-packages/wandb/apis/normalize.py", line 41, in wrapper
    return func(*args, **kwargs)
  File "/anaconda/envs/final_project_env/lib/python3.8/site-packages/wandb/sdk/internal/internal_api.py", line 1077, in sweep
    raise ValueError(f"Sweep {entity}/{project}/{sweep} not found")
ValueError: Sweep ravid-d/NLP2024_PROJECT_RavidDimant/zv3h8t0y not found

During handling of the above exception, another exception occurred:

Traceback (most recent call last):
  File "/anaconda/envs/final_project_env/lib/python3.8/site-packages/wandb/cli/cli.py", line 108, in wrapper
    return func(*args, **kwargs)
  File "/anaconda/envs/final_project_env/lib/python3.8/site-packages/wandb/cli/cli.py", line 1846, in agent
    wandb_agent.agent(sweep_id, entity=entity, project=project, count=count)
  File "/anaconda/envs/final_project_env/lib/python3.8/site-packages/wandb/wandb_agent.py", line 572, in agent
    return run_agent(
  File "/anaconda/envs/final_project_env/lib/python3.8/site-packages/wandb/wandb_agent.py", line 530, in run_agent
    agent.run()
  File "/anaconda/envs/final_project_env/lib/python3.8/site-packages/wandb/wandb_agent.py", line 192, in run
    sweep_obj = self._api.sweep(self._sweep_id, "{}")
  File "/anaconda/envs/final_project_env/lib/python3.8/site-packages/wandb/apis/internal.py", line 130, in sweep
    return self.api.sweep(*args, **kwargs)
  File "/anaconda/envs/final_project_env/lib/python3.8/site-packages/wandb/apis/normalize.py", line 87, in wrapper
    raise CommError(message, err).with_traceback(sys.exc_info()[2])
  File "/anaconda/envs/final_project_env/lib/python3.8/site-packages/wandb/apis/normalize.py", line 41, in wrapper
    return func(*args, **kwargs)
  File "/anaconda/envs/final_project_env/lib/python3.8/site-packages/wandb/sdk/internal/internal_api.py", line 1077, in sweep
    raise ValueError(f"Sweep {entity}/{project}/{sweep} not found")
wandb.errors.errors.CommError: Sweep ravid-d/NLP2024_PROJECT_RavidDimant/zv3h8t0y not found

2024-09-29 13:00:19 ERROR Traceback (most recent call last):
  File "/anaconda/envs/final_project_env/lib/python3.8/site-packages/wandb/apis/normalize.py", line 41, in wrapper
    return func(*args, **kwargs)
  File "/anaconda/envs/final_project_env/lib/python3.8/site-packages/wandb/sdk/internal/internal_api.py", line 1077, in sweep
    raise ValueError(f"Sweep {entity}/{project}/{sweep} not found")
ValueError: Sweep ravid-d/NLP2024_PROJECT_RavidDimant/zv3h8t0y not found

During handling of the above exception, another exception occurred:

Traceback (most recent call last):
  File "/anaconda/envs/final_project_env/lib/python3.8/site-packages/wandb/cli/cli.py", line 108, in wrapper
    return func(*args, **kwargs)
  File "/anaconda/envs/final_project_env/lib/python3.8/site-packages/wandb/cli/cli.py", line 1846, in agent
    wandb_agent.agent(sweep_id, entity=entity, project=project, count=count)
  File "/anaconda/envs/final_project_env/lib/python3.8/site-packages/wandb/wandb_agent.py", line 572, in agent
    return run_agent(
  File "/anaconda/envs/final_project_env/lib/python3.8/site-packages/wandb/wandb_agent.py", line 530, in run_agent
    agent.run()
  File "/anaconda/envs/final_project_env/lib/python3.8/site-packages/wandb/wandb_agent.py", line 192, in run
    sweep_obj = self._api.sweep(self._sweep_id, "{}")
  File "/anaconda/envs/final_project_env/lib/python3.8/site-packages/wandb/apis/internal.py", line 130, in sweep
    return self.api.sweep(*args, **kwargs)
  File "/anaconda/envs/final_project_env/lib/python3.8/site-packages/wandb/apis/normalize.py", line 87, in wrapper
    raise CommError(message, err).with_traceback(sys.exc_info()[2])
  File "/anaconda/envs/final_project_env/lib/python3.8/site-packages/wandb/apis/normalize.py", line 41, in wrapper
    return func(*args, **kwargs)
  File "/anaconda/envs/final_project_env/lib/python3.8/site-packages/wandb/sdk/internal/internal_api.py", line 1077, in sweep
    raise ValueError(f"Sweep {entity}/{project}/{sweep} not found")
wandb.errors.errors.CommError: Sweep ravid-d/NLP2024_PROJECT_RavidDimant/zv3h8t0y not found

2024-09-29 13:00:24 ERROR Traceback (most recent call last):
  File "/anaconda/envs/final_project_env/lib/python3.8/site-packages/wandb/apis/normalize.py", line 41, in wrapper
    return func(*args, **kwargs)
  File "/anaconda/envs/final_project_env/lib/python3.8/site-packages/wandb/sdk/internal/internal_api.py", line 1077, in sweep
    raise ValueError(f"Sweep {entity}/{project}/{sweep} not found")
ValueError: Sweep ravid-d/NLP2024_PROJECT_RavidDimant/zv3h8t0y not found

During handling of the above exception, another exception occurred:

Traceback (most recent call last):
  File "/anaconda/envs/final_project_env/lib/python3.8/site-packages/wandb/cli/cli.py", line 108, in wrapper
    return func(*args, **kwargs)
  File "/anaconda/envs/final_project_env/lib/python3.8/site-packages/wandb/cli/cli.py", line 1846, in agent
    wandb_agent.agent(sweep_id, entity=entity, project=project, count=count)
  File "/anaconda/envs/final_project_env/lib/python3.8/site-packages/wandb/wandb_agent.py", line 572, in agent
    return run_agent(
  File "/anaconda/envs/final_project_env/lib/python3.8/site-packages/wandb/wandb_agent.py", line 530, in run_agent
    agent.run()
  File "/anaconda/envs/final_project_env/lib/python3.8/site-packages/wandb/wandb_agent.py", line 192, in run
    sweep_obj = self._api.sweep(self._sweep_id, "{}")
  File "/anaconda/envs/final_project_env/lib/python3.8/site-packages/wandb/apis/internal.py", line 130, in sweep
    return self.api.sweep(*args, **kwargs)
  File "/anaconda/envs/final_project_env/lib/python3.8/site-packages/wandb/apis/normalize.py", line 87, in wrapper
    raise CommError(message, err).with_traceback(sys.exc_info()[2])
  File "/anaconda/envs/final_project_env/lib/python3.8/site-packages/wandb/apis/normalize.py", line 41, in wrapper
    return func(*args, **kwargs)
  File "/anaconda/envs/final_project_env/lib/python3.8/site-packages/wandb/sdk/internal/internal_api.py", line 1077, in sweep
    raise ValueError(f"Sweep {entity}/{project}/{sweep} not found")
wandb.errors.errors.CommError: Sweep ravid-d/NLP2024_PROJECT_RavidDimant/zv3h8t0y not found

2024-09-29 13:00:30 ERROR Traceback (most recent call last):
  File "/anaconda/envs/final_project_env/lib/python3.8/site-packages/wandb/apis/normalize.py", line 41, in wrapper
    return func(*args, **kwargs)
  File "/anaconda/envs/final_project_env/lib/python3.8/site-packages/wandb/sdk/internal/internal_api.py", line 1077, in sweep
    raise ValueError(f"Sweep {entity}/{project}/{sweep} not found")
ValueError: Sweep ravid-d/NLP2024_PROJECT_RavidDimant/zv3h8t0y not found

During handling of the above exception, another exception occurred:

Traceback (most recent call last):
  File "/anaconda/envs/final_project_env/lib/python3.8/site-packages/wandb/cli/cli.py", line 108, in wrapper
    return func(*args, **kwargs)
  File "/anaconda/envs/final_project_env/lib/python3.8/site-packages/wandb/cli/cli.py", line 1846, in agent
    wandb_agent.agent(sweep_id, entity=entity, project=project, count=count)
  File "/anaconda/envs/final_project_env/lib/python3.8/site-packages/wandb/wandb_agent.py", line 572, in agent
    return run_agent(
  File "/anaconda/envs/final_project_env/lib/python3.8/site-packages/wandb/wandb_agent.py", line 530, in run_agent
    agent.run()
  File "/anaconda/envs/final_project_env/lib/python3.8/site-packages/wandb/wandb_agent.py", line 192, in run
    sweep_obj = self._api.sweep(self._sweep_id, "{}")
  File "/anaconda/envs/final_project_env/lib/python3.8/site-packages/wandb/apis/internal.py", line 130, in sweep
    return self.api.sweep(*args, **kwargs)
  File "/anaconda/envs/final_project_env/lib/python3.8/site-packages/wandb/apis/normalize.py", line 87, in wrapper
    raise CommError(message, err).with_traceback(sys.exc_info()[2])
  File "/anaconda/envs/final_project_env/lib/python3.8/site-packages/wandb/apis/normalize.py", line 41, in wrapper
    return func(*args, **kwargs)
  File "/anaconda/envs/final_project_env/lib/python3.8/site-packages/wandb/sdk/internal/internal_api.py", line 1077, in sweep
    raise ValueError(f"Sweep {entity}/{project}/{sweep} not found")
wandb.errors.errors.CommError: Sweep ravid-d/NLP2024_PROJECT_RavidDimant/zv3h8t0y not found

2024-09-29 13:00:35 ERROR Traceback (most recent call last):
  File "/anaconda/envs/final_project_env/lib/python3.8/site-packages/wandb/apis/normalize.py", line 41, in wrapper
    return func(*args, **kwargs)
  File "/anaconda/envs/final_project_env/lib/python3.8/site-packages/wandb/sdk/internal/internal_api.py", line 1077, in sweep
    raise ValueError(f"Sweep {entity}/{project}/{sweep} not found")
ValueError: Sweep ravid-d/NLP2024_PROJECT_RavidDimant/zv3h8t0y not found

During handling of the above exception, another exception occurred:

Traceback (most recent call last):
  File "/anaconda/envs/final_project_env/lib/python3.8/site-packages/wandb/cli/cli.py", line 108, in wrapper
    return func(*args, **kwargs)
  File "/anaconda/envs/final_project_env/lib/python3.8/site-packages/wandb/cli/cli.py", line 1846, in agent
    wandb_agent.agent(sweep_id, entity=entity, project=project, count=count)
  File "/anaconda/envs/final_project_env/lib/python3.8/site-packages/wandb/wandb_agent.py", line 572, in agent
    return run_agent(
  File "/anaconda/envs/final_project_env/lib/python3.8/site-packages/wandb/wandb_agent.py", line 530, in run_agent
    agent.run()
  File "/anaconda/envs/final_project_env/lib/python3.8/site-packages/wandb/wandb_agent.py", line 192, in run
    sweep_obj = self._api.sweep(self._sweep_id, "{}")
  File "/anaconda/envs/final_project_env/lib/python3.8/site-packages/wandb/apis/internal.py", line 130, in sweep
    return self.api.sweep(*args, **kwargs)
  File "/anaconda/envs/final_project_env/lib/python3.8/site-packages/wandb/apis/normalize.py", line 87, in wrapper
    raise CommError(message, err).with_traceback(sys.exc_info()[2])
  File "/anaconda/envs/final_project_env/lib/python3.8/site-packages/wandb/apis/normalize.py", line 41, in wrapper
    return func(*args, **kwargs)
  File "/anaconda/envs/final_project_env/lib/python3.8/site-packages/wandb/sdk/internal/internal_api.py", line 1077, in sweep
    raise ValueError(f"Sweep {entity}/{project}/{sweep} not found")
wandb.errors.errors.CommError: Sweep ravid-d/NLP2024_PROJECT_RavidDimant/zv3h8t0y not found

2024-09-29 15:52:34 ERROR Traceback (most recent call last):
  File "/anaconda/envs/final_project_env/lib/python3.8/site-packages/wandb/apis/normalize.py", line 41, in wrapper
    return func(*args, **kwargs)
  File "/anaconda/envs/final_project_env/lib/python3.8/site-packages/wandb/sdk/internal/internal_api.py", line 1077, in sweep
    raise ValueError(f"Sweep {entity}/{project}/{sweep} not found")
ValueError: Sweep ravid-d/NLP2024_PROJECT_RavidDimant/trr0by60 not found

During handling of the above exception, another exception occurred:

Traceback (most recent call last):
  File "/anaconda/envs/final_project_env/lib/python3.8/site-packages/wandb/cli/cli.py", line 108, in wrapper
    return func(*args, **kwargs)
  File "/anaconda/envs/final_project_env/lib/python3.8/site-packages/wandb/cli/cli.py", line 1846, in agent
    wandb_agent.agent(sweep_id, entity=entity, project=project, count=count)
  File "/anaconda/envs/final_project_env/lib/python3.8/site-packages/wandb/wandb_agent.py", line 572, in agent
    return run_agent(
  File "/anaconda/envs/final_project_env/lib/python3.8/site-packages/wandb/wandb_agent.py", line 530, in run_agent
    agent.run()
  File "/anaconda/envs/final_project_env/lib/python3.8/site-packages/wandb/wandb_agent.py", line 192, in run
    sweep_obj = self._api.sweep(self._sweep_id, "{}")
  File "/anaconda/envs/final_project_env/lib/python3.8/site-packages/wandb/apis/internal.py", line 130, in sweep
    return self.api.sweep(*args, **kwargs)
  File "/anaconda/envs/final_project_env/lib/python3.8/site-packages/wandb/apis/normalize.py", line 87, in wrapper
    raise CommError(message, err).with_traceback(sys.exc_info()[2])
  File "/anaconda/envs/final_project_env/lib/python3.8/site-packages/wandb/apis/normalize.py", line 41, in wrapper
    return func(*args, **kwargs)
  File "/anaconda/envs/final_project_env/lib/python3.8/site-packages/wandb/sdk/internal/internal_api.py", line 1077, in sweep
    raise ValueError(f"Sweep {entity}/{project}/{sweep} not found")
wandb.errors.errors.CommError: Sweep ravid-d/NLP2024_PROJECT_RavidDimant/trr0by60 not found

2024-09-29 16:21:59 ERROR Traceback (most recent call last):
  File "/anaconda/envs/final_project_env/lib/python3.8/site-packages/wandb/apis/normalize.py", line 41, in wrapper
    return func(*args, **kwargs)
  File "/anaconda/envs/final_project_env/lib/python3.8/site-packages/wandb/sdk/internal/internal_api.py", line 1077, in sweep
    raise ValueError(f"Sweep {entity}/{project}/{sweep} not found")
ValueError: Sweep ravid-d/NLP2024_PROJECT_RavidDimant/2pirop5c not found

During handling of the above exception, another exception occurred:

Traceback (most recent call last):
  File "/anaconda/envs/final_project_env/lib/python3.8/site-packages/wandb/cli/cli.py", line 108, in wrapper
    return func(*args, **kwargs)
  File "/anaconda/envs/final_project_env/lib/python3.8/site-packages/wandb/cli/cli.py", line 1846, in agent
    wandb_agent.agent(sweep_id, entity=entity, project=project, count=count)
  File "/anaconda/envs/final_project_env/lib/python3.8/site-packages/wandb/wandb_agent.py", line 572, in agent
    return run_agent(
  File "/anaconda/envs/final_project_env/lib/python3.8/site-packages/wandb/wandb_agent.py", line 530, in run_agent
    agent.run()
  File "/anaconda/envs/final_project_env/lib/python3.8/site-packages/wandb/wandb_agent.py", line 192, in run
    sweep_obj = self._api.sweep(self._sweep_id, "{}")
  File "/anaconda/envs/final_project_env/lib/python3.8/site-packages/wandb/apis/internal.py", line 130, in sweep
    return self.api.sweep(*args, **kwargs)
  File "/anaconda/envs/final_project_env/lib/python3.8/site-packages/wandb/apis/normalize.py", line 87, in wrapper
    raise CommError(message, err).with_traceback(sys.exc_info()[2])
  File "/anaconda/envs/final_project_env/lib/python3.8/site-packages/wandb/apis/normalize.py", line 41, in wrapper
    return func(*args, **kwargs)
  File "/anaconda/envs/final_project_env/lib/python3.8/site-packages/wandb/sdk/internal/internal_api.py", line 1077, in sweep
    raise ValueError(f"Sweep {entity}/{project}/{sweep} not found")
wandb.errors.errors.CommError: Sweep ravid-d/NLP2024_PROJECT_RavidDimant/2pirop5c not found

2024-09-29 16:22:10 ERROR Traceback (most recent call last):
  File "/anaconda/envs/final_project_env/lib/python3.8/site-packages/wandb/apis/normalize.py", line 41, in wrapper
    return func(*args, **kwargs)
  File "/anaconda/envs/final_project_env/lib/python3.8/site-packages/wandb/sdk/internal/internal_api.py", line 1077, in sweep
    raise ValueError(f"Sweep {entity}/{project}/{sweep} not found")
ValueError: Sweep ravid-d/NLP2024_PROJECT_RavidDimant/2pirop5c not found

During handling of the above exception, another exception occurred:

Traceback (most recent call last):
  File "/anaconda/envs/final_project_env/lib/python3.8/site-packages/wandb/cli/cli.py", line 108, in wrapper
    return func(*args, **kwargs)
  File "/anaconda/envs/final_project_env/lib/python3.8/site-packages/wandb/cli/cli.py", line 1846, in agent
    wandb_agent.agent(sweep_id, entity=entity, project=project, count=count)
  File "/anaconda/envs/final_project_env/lib/python3.8/site-packages/wandb/wandb_agent.py", line 572, in agent
    return run_agent(
  File "/anaconda/envs/final_project_env/lib/python3.8/site-packages/wandb/wandb_agent.py", line 530, in run_agent
    agent.run()
  File "/anaconda/envs/final_project_env/lib/python3.8/site-packages/wandb/wandb_agent.py", line 192, in run
    sweep_obj = self._api.sweep(self._sweep_id, "{}")
  File "/anaconda/envs/final_project_env/lib/python3.8/site-packages/wandb/apis/internal.py", line 130, in sweep
    return self.api.sweep(*args, **kwargs)
  File "/anaconda/envs/final_project_env/lib/python3.8/site-packages/wandb/apis/normalize.py", line 87, in wrapper
    raise CommError(message, err).with_traceback(sys.exc_info()[2])
  File "/anaconda/envs/final_project_env/lib/python3.8/site-packages/wandb/apis/normalize.py", line 41, in wrapper
    return func(*args, **kwargs)
  File "/anaconda/envs/final_project_env/lib/python3.8/site-packages/wandb/sdk/internal/internal_api.py", line 1077, in sweep
    raise ValueError(f"Sweep {entity}/{project}/{sweep} not found")
wandb.errors.errors.CommError: Sweep ravid-d/NLP2024_PROJECT_RavidDimant/2pirop5c not found

2024-09-29 16:22:20 ERROR Traceback (most recent call last):
  File "/anaconda/envs/final_project_env/lib/python3.8/site-packages/wandb/apis/normalize.py", line 41, in wrapper
    return func(*args, **kwargs)
  File "/anaconda/envs/final_project_env/lib/python3.8/site-packages/wandb/sdk/internal/internal_api.py", line 1077, in sweep
    raise ValueError(f"Sweep {entity}/{project}/{sweep} not found")
ValueError: Sweep ravid-d/NLP2024_PROJECT_RavidDimant/2pirop5c not found

During handling of the above exception, another exception occurred:

Traceback (most recent call last):
  File "/anaconda/envs/final_project_env/lib/python3.8/site-packages/wandb/cli/cli.py", line 108, in wrapper
    return func(*args, **kwargs)
  File "/anaconda/envs/final_project_env/lib/python3.8/site-packages/wandb/cli/cli.py", line 1846, in agent
    wandb_agent.agent(sweep_id, entity=entity, project=project, count=count)
  File "/anaconda/envs/final_project_env/lib/python3.8/site-packages/wandb/wandb_agent.py", line 572, in agent
    return run_agent(
  File "/anaconda/envs/final_project_env/lib/python3.8/site-packages/wandb/wandb_agent.py", line 530, in run_agent
    agent.run()
  File "/anaconda/envs/final_project_env/lib/python3.8/site-packages/wandb/wandb_agent.py", line 192, in run
    sweep_obj = self._api.sweep(self._sweep_id, "{}")
  File "/anaconda/envs/final_project_env/lib/python3.8/site-packages/wandb/apis/internal.py", line 130, in sweep
    return self.api.sweep(*args, **kwargs)
  File "/anaconda/envs/final_project_env/lib/python3.8/site-packages/wandb/apis/normalize.py", line 87, in wrapper
    raise CommError(message, err).with_traceback(sys.exc_info()[2])
  File "/anaconda/envs/final_project_env/lib/python3.8/site-packages/wandb/apis/normalize.py", line 41, in wrapper
    return func(*args, **kwargs)
  File "/anaconda/envs/final_project_env/lib/python3.8/site-packages/wandb/sdk/internal/internal_api.py", line 1077, in sweep
    raise ValueError(f"Sweep {entity}/{project}/{sweep} not found")
wandb.errors.errors.CommError: Sweep ravid-d/NLP2024_PROJECT_RavidDimant/2pirop5c not found

2024-09-29 16:22:28 ERROR Traceback (most recent call last):
  File "/anaconda/envs/final_project_env/lib/python3.8/site-packages/wandb/apis/normalize.py", line 41, in wrapper
    return func(*args, **kwargs)
  File "/anaconda/envs/final_project_env/lib/python3.8/site-packages/wandb/sdk/internal/internal_api.py", line 1077, in sweep
    raise ValueError(f"Sweep {entity}/{project}/{sweep} not found")
ValueError: Sweep ravid-d/NLP2024_PROJECT_RavidDimant/2pirop5c not found

During handling of the above exception, another exception occurred:

Traceback (most recent call last):
  File "/anaconda/envs/final_project_env/lib/python3.8/site-packages/wandb/cli/cli.py", line 108, in wrapper
    return func(*args, **kwargs)
  File "/anaconda/envs/final_project_env/lib/python3.8/site-packages/wandb/cli/cli.py", line 1846, in agent
    wandb_agent.agent(sweep_id, entity=entity, project=project, count=count)
  File "/anaconda/envs/final_project_env/lib/python3.8/site-packages/wandb/wandb_agent.py", line 572, in agent
    return run_agent(
  File "/anaconda/envs/final_project_env/lib/python3.8/site-packages/wandb/wandb_agent.py", line 530, in run_agent
    agent.run()
  File "/anaconda/envs/final_project_env/lib/python3.8/site-packages/wandb/wandb_agent.py", line 192, in run
    sweep_obj = self._api.sweep(self._sweep_id, "{}")
  File "/anaconda/envs/final_project_env/lib/python3.8/site-packages/wandb/apis/internal.py", line 130, in sweep
    return self.api.sweep(*args, **kwargs)
  File "/anaconda/envs/final_project_env/lib/python3.8/site-packages/wandb/apis/normalize.py", line 87, in wrapper
    raise CommError(message, err).with_traceback(sys.exc_info()[2])
  File "/anaconda/envs/final_project_env/lib/python3.8/site-packages/wandb/apis/normalize.py", line 41, in wrapper
    return func(*args, **kwargs)
  File "/anaconda/envs/final_project_env/lib/python3.8/site-packages/wandb/sdk/internal/internal_api.py", line 1077, in sweep
    raise ValueError(f"Sweep {entity}/{project}/{sweep} not found")
wandb.errors.errors.CommError: Sweep ravid-d/NLP2024_PROJECT_RavidDimant/2pirop5c not found

2024-09-29 16:22:37 ERROR Traceback (most recent call last):
  File "/anaconda/envs/final_project_env/lib/python3.8/site-packages/wandb/apis/normalize.py", line 41, in wrapper
    return func(*args, **kwargs)
  File "/anaconda/envs/final_project_env/lib/python3.8/site-packages/wandb/sdk/internal/internal_api.py", line 1077, in sweep
    raise ValueError(f"Sweep {entity}/{project}/{sweep} not found")
ValueError: Sweep ravid-d/NLP2024_PROJECT_RavidDimant/2pirop5c not found

During handling of the above exception, another exception occurred:

Traceback (most recent call last):
  File "/anaconda/envs/final_project_env/lib/python3.8/site-packages/wandb/cli/cli.py", line 108, in wrapper
    return func(*args, **kwargs)
  File "/anaconda/envs/final_project_env/lib/python3.8/site-packages/wandb/cli/cli.py", line 1846, in agent
    wandb_agent.agent(sweep_id, entity=entity, project=project, count=count)
  File "/anaconda/envs/final_project_env/lib/python3.8/site-packages/wandb/wandb_agent.py", line 572, in agent
    return run_agent(
  File "/anaconda/envs/final_project_env/lib/python3.8/site-packages/wandb/wandb_agent.py", line 530, in run_agent
    agent.run()
  File "/anaconda/envs/final_project_env/lib/python3.8/site-packages/wandb/wandb_agent.py", line 192, in run
    sweep_obj = self._api.sweep(self._sweep_id, "{}")
  File "/anaconda/envs/final_project_env/lib/python3.8/site-packages/wandb/apis/internal.py", line 130, in sweep
    return self.api.sweep(*args, **kwargs)
  File "/anaconda/envs/final_project_env/lib/python3.8/site-packages/wandb/apis/normalize.py", line 87, in wrapper
    raise CommError(message, err).with_traceback(sys.exc_info()[2])
  File "/anaconda/envs/final_project_env/lib/python3.8/site-packages/wandb/apis/normalize.py", line 41, in wrapper
    return func(*args, **kwargs)
  File "/anaconda/envs/final_project_env/lib/python3.8/site-packages/wandb/sdk/internal/internal_api.py", line 1077, in sweep
    raise ValueError(f"Sweep {entity}/{project}/{sweep} not found")
wandb.errors.errors.CommError: Sweep ravid-d/NLP2024_PROJECT_RavidDimant/2pirop5c not found

2024-09-29 16:22:45 ERROR Traceback (most recent call last):
  File "/anaconda/envs/final_project_env/lib/python3.8/site-packages/wandb/apis/normalize.py", line 41, in wrapper
    return func(*args, **kwargs)
  File "/anaconda/envs/final_project_env/lib/python3.8/site-packages/wandb/sdk/internal/internal_api.py", line 1077, in sweep
    raise ValueError(f"Sweep {entity}/{project}/{sweep} not found")
ValueError: Sweep ravid-d/NLP2024_PROJECT_RavidDimant/2pirop5c not found

During handling of the above exception, another exception occurred:

Traceback (most recent call last):
  File "/anaconda/envs/final_project_env/lib/python3.8/site-packages/wandb/cli/cli.py", line 108, in wrapper
    return func(*args, **kwargs)
  File "/anaconda/envs/final_project_env/lib/python3.8/site-packages/wandb/cli/cli.py", line 1846, in agent
    wandb_agent.agent(sweep_id, entity=entity, project=project, count=count)
  File "/anaconda/envs/final_project_env/lib/python3.8/site-packages/wandb/wandb_agent.py", line 572, in agent
    return run_agent(
  File "/anaconda/envs/final_project_env/lib/python3.8/site-packages/wandb/wandb_agent.py", line 530, in run_agent
    agent.run()
  File "/anaconda/envs/final_project_env/lib/python3.8/site-packages/wandb/wandb_agent.py", line 192, in run
    sweep_obj = self._api.sweep(self._sweep_id, "{}")
  File "/anaconda/envs/final_project_env/lib/python3.8/site-packages/wandb/apis/internal.py", line 130, in sweep
    return self.api.sweep(*args, **kwargs)
  File "/anaconda/envs/final_project_env/lib/python3.8/site-packages/wandb/apis/normalize.py", line 87, in wrapper
    raise CommError(message, err).with_traceback(sys.exc_info()[2])
  File "/anaconda/envs/final_project_env/lib/python3.8/site-packages/wandb/apis/normalize.py", line 41, in wrapper
    return func(*args, **kwargs)
  File "/anaconda/envs/final_project_env/lib/python3.8/site-packages/wandb/sdk/internal/internal_api.py", line 1077, in sweep
    raise ValueError(f"Sweep {entity}/{project}/{sweep} not found")
wandb.errors.errors.CommError: Sweep ravid-d/NLP2024_PROJECT_RavidDimant/2pirop5c not found

2024-10-01 10:36:13 ERROR Traceback (most recent call last):
  File "/anaconda/envs/final_project_env/lib/python3.8/site-packages/wandb/apis/normalize.py", line 41, in wrapper
    return func(*args, **kwargs)
  File "/anaconda/envs/final_project_env/lib/python3.8/site-packages/wandb/sdk/internal/internal_api.py", line 1077, in sweep
    raise ValueError(f"Sweep {entity}/{project}/{sweep} not found")
ValueError: Sweep ravid-d/NLP2024_PROJECT_RavidDimant/xeoy63uo not found

During handling of the above exception, another exception occurred:

Traceback (most recent call last):
  File "/anaconda/envs/final_project_env/lib/python3.8/site-packages/wandb/cli/cli.py", line 108, in wrapper
    return func(*args, **kwargs)
  File "/anaconda/envs/final_project_env/lib/python3.8/site-packages/wandb/cli/cli.py", line 1846, in agent
    wandb_agent.agent(sweep_id, entity=entity, project=project, count=count)
  File "/anaconda/envs/final_project_env/lib/python3.8/site-packages/wandb/wandb_agent.py", line 572, in agent
    return run_agent(
  File "/anaconda/envs/final_project_env/lib/python3.8/site-packages/wandb/wandb_agent.py", line 530, in run_agent
    agent.run()
  File "/anaconda/envs/final_project_env/lib/python3.8/site-packages/wandb/wandb_agent.py", line 192, in run
    sweep_obj = self._api.sweep(self._sweep_id, "{}")
  File "/anaconda/envs/final_project_env/lib/python3.8/site-packages/wandb/apis/internal.py", line 130, in sweep
    return self.api.sweep(*args, **kwargs)
  File "/anaconda/envs/final_project_env/lib/python3.8/site-packages/wandb/apis/normalize.py", line 87, in wrapper
    raise CommError(message, err).with_traceback(sys.exc_info()[2])
  File "/anaconda/envs/final_project_env/lib/python3.8/site-packages/wandb/apis/normalize.py", line 41, in wrapper
    return func(*args, **kwargs)
  File "/anaconda/envs/final_project_env/lib/python3.8/site-packages/wandb/sdk/internal/internal_api.py", line 1077, in sweep
    raise ValueError(f"Sweep {entity}/{project}/{sweep} not found")
wandb.errors.errors.CommError: Sweep ravid-d/NLP2024_PROJECT_RavidDimant/xeoy63uo not found

2024-10-01 10:39:09 ERROR Traceback (most recent call last):
  File "/anaconda/envs/final_project_env/lib/python3.8/site-packages/wandb/apis/normalize.py", line 41, in wrapper
    return func(*args, **kwargs)
  File "/anaconda/envs/final_project_env/lib/python3.8/site-packages/wandb/sdk/internal/internal_api.py", line 1077, in sweep
    raise ValueError(f"Sweep {entity}/{project}/{sweep} not found")
ValueError: Sweep ravid-d/NLP2024_PROJECT_RavidDimant/xeo not found

During handling of the above exception, another exception occurred:

Traceback (most recent call last):
  File "/anaconda/envs/final_project_env/lib/python3.8/site-packages/wandb/cli/cli.py", line 108, in wrapper
    return func(*args, **kwargs)
  File "/anaconda/envs/final_project_env/lib/python3.8/site-packages/wandb/cli/cli.py", line 1846, in agent
    wandb_agent.agent(sweep_id, entity=entity, project=project, count=count)
  File "/anaconda/envs/final_project_env/lib/python3.8/site-packages/wandb/wandb_agent.py", line 572, in agent
    return run_agent(
  File "/anaconda/envs/final_project_env/lib/python3.8/site-packages/wandb/wandb_agent.py", line 530, in run_agent
    agent.run()
  File "/anaconda/envs/final_project_env/lib/python3.8/site-packages/wandb/wandb_agent.py", line 192, in run
    sweep_obj = self._api.sweep(self._sweep_id, "{}")
  File "/anaconda/envs/final_project_env/lib/python3.8/site-packages/wandb/apis/internal.py", line 130, in sweep
    return self.api.sweep(*args, **kwargs)
  File "/anaconda/envs/final_project_env/lib/python3.8/site-packages/wandb/apis/normalize.py", line 87, in wrapper
    raise CommError(message, err).with_traceback(sys.exc_info()[2])
  File "/anaconda/envs/final_project_env/lib/python3.8/site-packages/wandb/apis/normalize.py", line 41, in wrapper
    return func(*args, **kwargs)
  File "/anaconda/envs/final_project_env/lib/python3.8/site-packages/wandb/sdk/internal/internal_api.py", line 1077, in sweep
    raise ValueError(f"Sweep {entity}/{project}/{sweep} not found")
wandb.errors.errors.CommError: Sweep ravid-d/NLP2024_PROJECT_RavidDimant/xeo not found

2024-10-01 14:06:54 ERROR Traceback (most recent call last):
  File "/anaconda/envs/final_project_env/lib/python3.8/site-packages/wandb/apis/normalize.py", line 41, in wrapper
    return func(*args, **kwargs)
  File "/anaconda/envs/final_project_env/lib/python3.8/site-packages/wandb/sdk/internal/internal_api.py", line 1077, in sweep
    raise ValueError(f"Sweep {entity}/{project}/{sweep} not found")
ValueError: Sweep ravid-d/NLP2024_PROJECT_RavidDimant/88fee11d not found

During handling of the above exception, another exception occurred:

Traceback (most recent call last):
  File "/anaconda/envs/final_project_env/lib/python3.8/site-packages/wandb/cli/cli.py", line 108, in wrapper
    return func(*args, **kwargs)
  File "/anaconda/envs/final_project_env/lib/python3.8/site-packages/wandb/cli/cli.py", line 1846, in agent
    wandb_agent.agent(sweep_id, entity=entity, project=project, count=count)
  File "/anaconda/envs/final_project_env/lib/python3.8/site-packages/wandb/wandb_agent.py", line 572, in agent
    return run_agent(
  File "/anaconda/envs/final_project_env/lib/python3.8/site-packages/wandb/wandb_agent.py", line 530, in run_agent
    agent.run()
  File "/anaconda/envs/final_project_env/lib/python3.8/site-packages/wandb/wandb_agent.py", line 192, in run
    sweep_obj = self._api.sweep(self._sweep_id, "{}")
  File "/anaconda/envs/final_project_env/lib/python3.8/site-packages/wandb/apis/internal.py", line 130, in sweep
    return self.api.sweep(*args, **kwargs)
  File "/anaconda/envs/final_project_env/lib/python3.8/site-packages/wandb/apis/normalize.py", line 87, in wrapper
    raise CommError(message, err).with_traceback(sys.exc_info()[2])
  File "/anaconda/envs/final_project_env/lib/python3.8/site-packages/wandb/apis/normalize.py", line 41, in wrapper
    return func(*args, **kwargs)
  File "/anaconda/envs/final_project_env/lib/python3.8/site-packages/wandb/sdk/internal/internal_api.py", line 1077, in sweep
    raise ValueError(f"Sweep {entity}/{project}/{sweep} not found")
wandb.errors.errors.CommError: Sweep ravid-d/NLP2024_PROJECT_RavidDimant/88fee11d not found

2024-10-01 14:10:07 INFO Running runs: []
2024-10-01 14:10:07 INFO Agent received command: run
2024-10-01 14:10:07 INFO Agent starting run with config:
	ENV_HPT_mode: False
	bot_strategy_prob: 0
	seed: 2
2024-10-01 14:10:07 INFO About to run command: python StrategyTransfer.py --ENV_HPT_mode=False --bot_strategy_prob=0 --seed=2
2024-10-01 14:10:12 INFO Running runs: ['qfjede0w']
2024-10-01 14:10:12 INFO Cleaning up finished run: qfjede0w
2024-10-01 14:10:13 INFO Agent received command: run
2024-10-01 14:10:13 INFO Agent starting run with config:
	ENV_HPT_mode: False
	bot_strategy_prob: 0
	seed: 3
2024-10-01 14:10:13 INFO About to run command: python StrategyTransfer.py --ENV_HPT_mode=False --bot_strategy_prob=0 --seed=3
2024-10-01 14:10:18 INFO Running runs: ['3zn1uaif']
2024-10-01 14:10:18 INFO Cleaning up finished run: 3zn1uaif
2024-10-01 14:10:18 INFO Agent received command: run
2024-10-01 14:10:18 INFO Agent starting run with config:
	ENV_HPT_mode: False
	bot_strategy_prob: 0
	seed: 4
2024-10-01 14:10:18 INFO About to run command: python StrategyTransfer.py --ENV_HPT_mode=False --bot_strategy_prob=0 --seed=4
2024-10-01 14:10:23 INFO Running runs: ['30m96l65']
2024-10-01 14:10:23 ERROR Detected 3 failed runs in the first 60 seconds, shutting down.
2024-10-01 14:10:23 INFO To disable this check set WANDB_AGENT_DISABLE_FLAPPING=true
2024-10-01 14:11:13 INFO Running runs: []
2024-10-01 14:11:13 INFO Agent received command: run
2024-10-01 14:11:13 INFO Agent starting run with config:
	ENV_HPT_mode: False
	bot_strategy_prob: 0
	seed: 5
2024-10-01 14:11:13 INFO About to run command: python StrategyTransfer.py --ENV_HPT_mode=False --bot_strategy_prob=0 --seed=5
2024-10-01 14:11:18 INFO Running runs: ['f17t989m']
2024-10-01 14:11:18 INFO Cleaning up finished run: f17t989m
2024-10-01 14:11:18 INFO Agent received command: run
2024-10-01 14:11:18 INFO Agent starting run with config:
	ENV_HPT_mode: False
	bot_strategy_prob: 0.25
	seed: 1
2024-10-01 14:11:18 INFO About to run command: python StrategyTransfer.py --ENV_HPT_mode=False --bot_strategy_prob=0.25 --seed=1
2024-10-01 14:11:23 INFO Running runs: ['wb1fcp8d']
2024-10-01 14:11:23 INFO Cleaning up finished run: wb1fcp8d
2024-10-01 14:11:24 INFO Agent received command: run
2024-10-01 14:11:24 INFO Agent starting run with config:
	ENV_HPT_mode: False
	bot_strategy_prob: 0.25
	seed: 2
2024-10-01 14:11:24 INFO About to run command: python StrategyTransfer.py --ENV_HPT_mode=False --bot_strategy_prob=0.25 --seed=2
2024-10-01 14:11:29 INFO Running runs: ['izndobrj']
2024-10-01 14:11:29 ERROR Detected 3 failed runs in the first 60 seconds, shutting down.
2024-10-01 14:11:29 INFO To disable this check set WANDB_AGENT_DISABLE_FLAPPING=true
2024-10-02 11:29:58 INFO Running runs: []
2024-10-02 11:29:59 INFO Agent received command: run
2024-10-02 11:29:59 INFO Agent starting run with config:
	ENV_HPT_mode: False
	bot_strategy_prob: 0
	seed: 1
2024-10-02 11:29:59 INFO About to run command: python StrategyTransfer.py --ENV_HPT_mode=False --bot_strategy_prob=0 --seed=1
2024-10-02 11:30:04 INFO Running runs: ['2aca6hli']
2024-10-02 11:30:04 INFO Cleaning up finished run: 2aca6hli
2024-10-02 11:30:04 INFO Agent received command: run
2024-10-02 11:30:04 INFO Agent starting run with config:
	ENV_HPT_mode: False
	bot_strategy_prob: 0
	seed: 2
2024-10-02 11:30:04 INFO About to run command: python StrategyTransfer.py --ENV_HPT_mode=False --bot_strategy_prob=0 --seed=2
2024-10-02 11:30:09 INFO Running runs: ['2cmlq7t6']
2024-10-02 11:30:09 INFO Cleaning up finished run: 2cmlq7t6
2024-10-02 11:30:11 INFO Agent received command: run
2024-10-02 11:30:11 INFO Agent starting run with config:
	ENV_HPT_mode: False
	bot_strategy_prob: 0
	seed: 3
2024-10-02 11:30:11 INFO About to run command: python StrategyTransfer.py --ENV_HPT_mode=False --bot_strategy_prob=0 --seed=3
2024-10-02 11:30:16 INFO Running runs: ['wg4h25ng']
2024-10-02 11:30:16 ERROR Detected 3 failed runs in the first 60 seconds, shutting down.
2024-10-02 11:30:16 INFO To disable this check set WANDB_AGENT_DISABLE_FLAPPING=true
2024-10-02 11:41:44 INFO Running runs: []
2024-10-02 11:41:45 INFO Agent received command: run
2024-10-02 11:41:45 INFO Agent starting run with config:
	ENV_HPT_mode: False
	bot_strategy_prob: 0
	seed: 1
2024-10-02 11:41:45 INFO About to run command: python StrategyTransfer.py --ENV_HPT_mode=False --bot_strategy_prob=0 --seed=1
2024-10-02 11:41:50 INFO Running runs: ['vp3u2cnp']
2024-10-02 11:41:50 INFO Cleaning up finished run: vp3u2cnp
2024-10-02 11:41:50 INFO Agent received command: run
2024-10-02 11:41:50 INFO Agent starting run with config:
	ENV_HPT_mode: False
	bot_strategy_prob: 0
	seed: 2
2024-10-02 11:41:50 INFO About to run command: python StrategyTransfer.py --ENV_HPT_mode=False --bot_strategy_prob=0 --seed=2
2024-10-02 11:41:55 INFO Running runs: ['hv709830']
2024-10-02 11:41:55 INFO Cleaning up finished run: hv709830
2024-10-02 11:41:56 INFO Agent received command: run
2024-10-02 11:41:56 INFO Agent starting run with config:
	ENV_HPT_mode: False
	bot_strategy_prob: 0
	seed: 3
2024-10-02 11:41:56 INFO About to run command: python StrategyTransfer.py --ENV_HPT_mode=False --bot_strategy_prob=0 --seed=3
2024-10-02 11:42:01 INFO Running runs: ['yvno1902']
2024-10-02 11:42:01 ERROR Detected 3 failed runs in the first 60 seconds, shutting down.
2024-10-02 11:42:01 INFO To disable this check set WANDB_AGENT_DISABLE_FLAPPING=true
2024-10-02 12:50:28 ERROR 502 response executing GraphQL.
2024-10-02 12:50:28 ERROR 
<html><head>
<meta http-equiv="content-type" content="text/html;charset=utf-8">
<title>502 Server Error</title>
</head>
<body text=#000000 bgcolor=#ffffff>
<h1>Error: Server Error</h1>
<h2>The server encountered a temporary error and could not complete your request.<p>Please try again in 30 seconds.</h2>
<h2></h2>
</body></html>

2024-10-02 12:50:34 INFO Running runs: []
2024-10-02 12:50:34 INFO Agent received command: run
2024-10-02 12:50:34 INFO Agent starting run with config:
	ENV_HPT_mode: False
	bot_strategy_prob: 0
	seed: 1
2024-10-02 12:50:34 INFO About to run command: python StrategyTransfer.py --ENV_HPT_mode=False --bot_strategy_prob=0 --seed=1
2024-10-02 12:50:39 INFO Running runs: ['ic76ho62']
2024-10-02 12:50:39 INFO Cleaning up finished run: ic76ho62
2024-10-02 12:50:40 INFO Agent received command: run
2024-10-02 12:50:40 INFO Agent starting run with config:
	ENV_HPT_mode: False
	bot_strategy_prob: 0
	seed: 2
2024-10-02 12:50:40 INFO About to run command: python StrategyTransfer.py --ENV_HPT_mode=False --bot_strategy_prob=0 --seed=2
2024-10-02 12:50:45 INFO Running runs: ['25gsnwjq']
2024-10-02 12:50:45 INFO Cleaning up finished run: 25gsnwjq
2024-10-02 12:50:45 INFO Agent received command: run
2024-10-02 12:50:45 INFO Agent starting run with config:
	ENV_HPT_mode: False
	bot_strategy_prob: 0
	seed: 3
2024-10-02 12:50:45 INFO About to run command: python StrategyTransfer.py --ENV_HPT_mode=False --bot_strategy_prob=0 --seed=3
2024-10-02 12:50:50 INFO Running runs: ['k4mie2ol']
2024-10-02 12:50:50 ERROR Detected 3 failed runs in the first 60 seconds, shutting down.
2024-10-02 12:50:50 INFO To disable this check set WANDB_AGENT_DISABLE_FLAPPING=true
2024-10-03 01:28:09 INFO Running runs: []
2024-10-03 01:28:09 INFO Agent received command: run
2024-10-03 01:28:09 INFO Agent starting run with config:
	ENV_HPT_mode: False
	bot_strategy_prob: 0
	seed: 2
2024-10-03 01:28:09 INFO About to run command: python StrategyTransfer.py --ENV_HPT_mode=False --bot_strategy_prob=0 --seed=2
2024-10-03 01:28:14 INFO Running runs: ['55ybimiq']
2024-10-03 01:28:14 INFO Cleaning up finished run: 55ybimiq
2024-10-03 01:28:15 INFO Agent received command: run
2024-10-03 01:28:15 INFO Agent starting run with config:
	ENV_HPT_mode: False
	bot_strategy_prob: 0.25
	seed: 2
2024-10-03 01:28:15 INFO About to run command: python StrategyTransfer.py --ENV_HPT_mode=False --bot_strategy_prob=0.25 --seed=2
2024-10-03 01:28:20 INFO Running runs: ['2kjenznf']
2024-10-03 01:28:20 INFO Cleaning up finished run: 2kjenznf
2024-10-03 01:28:20 INFO Agent received command: run
2024-10-03 01:28:20 INFO Agent starting run with config:
	ENV_HPT_mode: False
	bot_strategy_prob: 0.5
	seed: 2
2024-10-03 01:28:20 INFO About to run command: python StrategyTransfer.py --ENV_HPT_mode=False --bot_strategy_prob=0.5 --seed=2
2024-10-03 01:28:25 INFO Running runs: ['5v0fxv25']
2024-10-03 01:28:25 ERROR Detected 3 failed runs in the first 60 seconds, shutting down.
2024-10-03 01:28:25 INFO To disable this check set WANDB_AGENT_DISABLE_FLAPPING=true
2024-10-03 01:48:26 INFO Running runs: []
2024-10-03 01:48:26 INFO Agent received command: run
2024-10-03 01:48:26 INFO Agent starting run with config:
	ENV_HPT_mode: False
	bot_strategy_prob: 0
	seed: 2
2024-10-03 01:48:26 INFO About to run command: python StrategyTransfer.py --ENV_HPT_mode=False --bot_strategy_prob=0 --seed=2
2024-10-03 01:48:31 INFO Running runs: ['ve4q232m']
2024-10-03 01:48:31 INFO Cleaning up finished run: ve4q232m
2024-10-03 01:48:32 INFO Agent received command: run
2024-10-03 01:48:32 INFO Agent starting run with config:
	ENV_HPT_mode: False
	bot_strategy_prob: 0.25
	seed: 2
2024-10-03 01:48:32 INFO About to run command: python StrategyTransfer.py --ENV_HPT_mode=False --bot_strategy_prob=0.25 --seed=2
2024-10-03 01:48:37 INFO Running runs: ['dd2rlzu3']
2024-10-03 01:48:37 INFO Cleaning up finished run: dd2rlzu3
2024-10-03 01:48:37 INFO Agent received command: run
2024-10-03 01:48:37 INFO Agent starting run with config:
	ENV_HPT_mode: False
	bot_strategy_prob: 0.5
	seed: 2
2024-10-03 01:48:37 INFO About to run command: python StrategyTransfer.py --ENV_HPT_mode=False --bot_strategy_prob=0.5 --seed=2
2024-10-03 01:48:42 INFO Running runs: ['3f2uzyog']
2024-10-03 01:48:42 ERROR Detected 3 failed runs in the first 60 seconds, shutting down.
2024-10-03 01:48:42 INFO To disable this check set WANDB_AGENT_DISABLE_FLAPPING=true
